Workbook

Sheet ПК с 1 владельцем
B1: Табельный номер / Employee ID | C1: Физлицо / Owner | D1: Статус пк ( была ли модернизация) / Modernisation, repairing history | E1: Тип домена / Domain Type | F1: Имя на английском / English name | G1: Должность / Position (Rus / Eng) | H1: Отдел / Department | I1: Комплектация / Equipment | J1: Тип и модель ПК / PC type and model | K1: Инвентарный номер / Inventory number | L1: Инвентарный номер наклеен? / Is the inventory number affixed? | M1: где хранится информация о компе | N1: Местоположение ПК / Location | O1: Серийный номер / Serial Number | P1: Имя компьютера / PC Domain Name | Q1: Passwork | R1: Тип ПО офис / Office type | S1: Ключ офиса / License key Office | T1: ОС тип / OS Type | U1: Ключ ОС / Key OS | V1: ПО удалённого управления / Remote control | W1: Админ права / Admin permissions | X1: Кто подготовил / Who installed | Y1: Дата выдачи / Issue Date | Z1: Дата покупки / Purchasing Date | AA1: Примечание / Comment
A2: =A1+1 -> 1 | B2: 36 | C2: Живов Сергей Викторович | D2: Модернизация не требуется/normal (no need to upgrade) | E2: Rus | G2: Заместитель генерального директора по производству | H2: MD | I2: Laptop,mouse | J2: Laptop ThinkBook 16 G7 ARP 3 | O2: PW0LW3V5 | P2: ="RUTL-" & RIGHT(O2,8) -> RUTL-PW0LW3V5 | R2: Libre office | T2: Windows 11 Pro | U2: 93TQN-DYGPM-FPQ9C-2X3QP-4RHJ6 | V2: ULTRAVNC / MESH | W2: No Administrator rights | X2: Мелёшкин С. | AA2: С НДС 64660 БЕЗ НДС 53000
A3: ='Склад, ремонт, ожидающие'!A44+1 -> #REF! | B3: 42 | C3: Денисов Леонид Алексеевич | D3: Модернизация не требуется/normal (no need to upgrade) | E3: Rus | F3: Denisov Leonid | G3: Ведущий специалист | H3: GD, GA, RMG | I3: AiO, mouse, keyboard | J3: AiO Lenovo S400Z | K3: 150000016/Z000014 | L3: Наклеить | N3: 1-07 третий этаж | O3: P901FSLR | P3: ="RUTL-" & RIGHT(O3,8) -> RUTL-P901FSLR | U3: QDRN8-XWVBK-KKTG9-7HM6W-7FTGC | V3: ULTRAVNC | W3: Уточнить | Y3: 2017
A4: =A3+1 -> #REF! | B4: 47 | C4: Верняев Александр Сергеевич (MSI+o) | D4: Модернизация не требуется/normal (no need to upgrade) | E4: Rus | F4: Vernyaev Aleksandr | G4: Заместитель директора департамента | H4: HRD | I4: Laptop, mouse, bag | J4: Laptop IRBIS 17NBP4502 | K4: поставить на учет | L4: Наклеить | N4: 1-07 третий этаж | O4: F2717NBP4502103035 | P4: ="RUTL-" & RIGHT(O4,8) -> RUTL-02103035 | Q4: Внесены в Passwork | R4: Libre office | S4: 39D7B-N3MY4-H97DG-KW8RW-78TTG | T4: Windows 10 Pro | U4: VK7JG-NPHTM-C97JM-9MPGT-3V66T | V4: ULTRAVNC / MESH | W4: No Administrator rights | X4: Кудрявцев Д. | Y4: Акт 24.03.2025
A5: =#REF!+1 -> #REF! | B5: 52 | C5: Онуфриев Сергей Юрьевич (052) | D5: Модернизация не требуется/normal (no need to upgrade) | E5: Rus | F5: Onufriev Sergey | G5: Директор департамента | H5: M&U | I5: Laptop, mouse,bag | J5: Laptop MSI Modern 15 F1MG-800XRU | K5: поставить на учет | L5: Наклеить | N5: 1-09 второй этаж | O5: C2507N0002971 | P5: ="RUTL-" & RIGHT(O5,8) -> RUTL-N0002971 | Q5: Внесены в Passwork | R5: 2019 for home and business | T5: Windows 11 Pro | U5: FNKPJ-D474G-6KX2R-DHVCM-TXX2P | V5: ULTRAVNC / MESH | W5: No administrator rights | X5: Летунов А. | Y5: Акт 04,04,2026 | Z5: 45987 | AA5: Стоимость ПК без НДС 59 160руб
A6: ='Склад, ремонт, ожидающие'!A37+1 -> #REF! | B6: 59 | C6: Самойленко Антон Викторович | D6: Модернизация не требуется/normal (no need to upgrade) | E6: Rus | F6: Samoylenko Anton | G6: Заместитель директора департамента | H6: M&U | I6: Laptop, mouse, bag | J6: Laptop MSI Modern 15 F1MG-800XRU | K6: поставить на учет | L6: Наклеить | N6: 1-13 крыло ютилити 2 эт | O6: C2509N0008357 | P6: ="RUTL-" & RIGHT(O6,8) -> RUTL-N0008357 | Q6: Внесены в Passwork | R6: MS Office 2019 Pro Plus | S6: NVP38-3P3F3-FDCCY-CPFYW-MTFW6 | T6: Windows 11 Pro | U6: HN6RT-B4HJP-KMKFG-G3VPV-4C2TC | V6: ULTRAVNC / MESH | W6: No Administrator rights | X6: Кудрявцев Д. | Y6: Акт 25.02.2026 | Z6: 45989 | AA6: Стоимость ПК без НДС 59 160руб
A7: =A6+1 -> #REF! | B7: 72 | C7: Зорин Сергей Александрович | D7: Модернизация не требуется/normal (no need to upgrade) Заменён SSD 256гб. | E7: Rus | F7: Zorin Sergey | G7: Руководитель отдела | H7: GD, CONSTR | I7: Workstation, Монитор Lenovo ThinkVision T2424z | J7: Workstation Lenovo ThinkStation P310 | K7: 150000029/Z000114 | L7: Наклеить | N7: строительный городок | O7: S4BP0247 | P7: ="RUTL-" & RIGHT(O7,8) -> RUTL-S4BP0247 | Q7: Внесены в Passwork | U7: P3W88-4NBCQ-K46F6-GPYDV-DRR9C | V7: ULTRAVNC | W7: No Administrator rights | Y7: 2016
A8: =A7+1 -> #REF! | B8: 85 | C8: Каприца Светлана Олеговна | D8: Модернизация не требуется/normal (no need to upgrade) | E8: Rus | F8: Kapritsa Svetlana | G8: Руководитель офисной группы | H8: NOBO GA | I8: Laptop, mouse,+lan USB | J8: Laptop Dell Inspiron 15 3511 | K8: 100000001659 | L8: Наклеить | O8: 5MB0JK3 | P8: ="RUTL-" & RIGHT(O8,8) -> RUTL-5MB0JK3 | Q8: Внесены в Passwork | T8: Windows 10 Pro | V8: ULTRAVNC / MESH | W8: No Administrator rights | X8: Мартынов Д. | Y8: Акт 26.01.2026 | Z8: 44551 | AA8: БЕЗ НДС 81250,00 с НДС 97500
A9: =A8+1 -> #REF! | B9: 92 | C9: Райкова Любовь Владимировна | D9: Модернизация не требуется/normal (no need to upgrade) | E9: Rus | F9: Raikova Lyubov | G9: Руководитель группы | H9: RDC, BSSS | I9: Laptop, mouse, Monitor MSI-27 | J9: Laptop MSI Modern 15 F1MG-800XRU | K9: поставить на учет | L9: Наклеить | N9: 1-07 2 этаж | O9: C2507N0002983 | P9: ="RUTL-" & RIGHT(O9,8) -> RUTL-N0002983 | Q9: Внесены в Passwork | R9: 2019 for home and business | T9: Windows 11 Pro | U9: R767N-6J8WQ-GC3FW-R6YC8-W44C2 | V9: ULTRAVNC / MESH | W9: Admin | X9: Летунов А. | Y9: Акт 03.12.2025 | Z9: 45989 | AA9: Стоимость ПК без НДС 59 160руб
A10: =A9+1 -> #REF! | B10: 101 | C10: Терехов Максим Сергеевич | D10: Модернизация не требуется/normal (no need to upgrade) \ Отказ от замены Пк | E10: Rus | F10: Terekhov Maksim | G10: Заместитель главного энергетика | H10: M&U, UTL | I10: Workstation,mouse, keyboard+ Monitor LG | J10: Workstation Lenovo ThinkStation P 320 | K10: 140000256 | L10: инвентарник ОС наклеен | N10: 1-13 крыло ютилити 2 эт | O10: PC10AS8Y | P10: ="RUTL-" & RIGHT(O10,8) -> RUTL-PC10AS8Y | Q10: Внесены в Passwork | R10: Microsoft Office профессиональный плюс 2016 | T10: Windows 10 Pro | U10: C84R9-KTNCH-DF739-H3KD4-YTDGP | V10: ULTRAVNC | W10: No Administrator rights | Y10: Акт 03.07.2019
A11: =A10+1 -> #REF! | B11: 119 | C11: Денисов Роман Альбертович | D11: Модернизация не требуется/normal (no need to upgrade) | E11: Rus | F11: Denisov Roman | G11: Руководитель группы | H11: ILD, CO | I11: Laptop,mouse+Lan-USB | J11: Laptop Asus VivoBook SS533 | K11: 10000001730 | L11: наклеить | N11: 1-06 второй этаж | O11: M3N0CV15E20911A | P11: ="RUTL-" & RIGHT(O11,8) -> RUTL-5E20911A | Q11: Внесены в Passwork | R11: Libre office | T11: Windows 10 Pro | V11: ULTRAVNC | W11: Уточнить | Y11: Акт 10.09.2021
A12: =A11+1 -> #REF! | B12: 120 | C12: Душкин Иван Александрович | D12: Модернизация не требуется/normal (no need to upgrade) | E12: Rus | F12: Dushkin Ivan | G12: Директор по правовым вопросам и внешним связям | H12: GD, LEG | I12: Laptop, mouse,bag | J12: Laptop Lenovo L340 | K12: 10000001791 | L12: инвентарник ОС наклеен | N12: 1-07 третий этаж | O12: PF24A8SV | P12: ="RUTL-" & RIGHT(O12,8) -> RUTL-PF24A8SV | Q12: Внесены в Passwork | R12: 2019 for home and business | T12: Windows 10 Pro | V12: ULTRAVNC | W12: Уточнить | Y12: Акт 26.02.2021
A13: =A12+1 -> #REF! | B13: 125 | C13: Морозов Антон Вячеславович | D13: требуется модернизация/ЗАМЕНА | E13: Rus | F13: Morozov Anton | G13: Инженер-электроник 2 категории | H13: M&U,MTC ASPC | I13: AiO, mouse, keyboard | J13: AiO Lenovo M800Z | K13: 140000064/Z000099 | L13: Наклеить | N13: 1-03 офис MU окраски 1эт | O13: PC0KL0LH | P13: ="RUTL-" & RIGHT(O13,8) -> RUTL-PC0KL0LH | Q13: Внесены в Passwork | T13: Windows 10 Pro | U13: CHN29-XHCDQ-8JCF9-8DTMQ-4GDGP | V13: ULTRAVNC | W13: No Administrator rights | Y13: 2018
A14: =A13+1 -> #REF! | B14: 135 | C14: Дудукина Ольга | D14: Модернизация не требуется/normal (no need to upgrade) | E14: Rus | F14: Dudukina Olga | G14: Руководитель группы | H14: GD, FPW | I14: Laptop,mouse | J14: Laptop Acer Extensa 15 | K14: 100000003330 | N14: 1-07 второй этаж | O14: NXEGYER00H3200884B3400 | P14: ="RUTL-" & RIGHT(O14,8) -> RUTL-884B3400 | Q14: Внесены в Passwork | R14: 2019 for home and business | T14: Windows 10 Pro | V14: ULTRAVNC | W14: Уточнить | Y14: Акт 08.05.2024 | Z14: 2024 | AA14: БЕЗ НДС 60440.50
A15: =A14+1 -> #REF! | B15: 140 | C15: Фадеева Надежда Петровна | D15: была модернизация/upgraded (SSD+RAM 8) | E15: Rus | F15: Fadeeva Nadezhda | G15: Ведущий инженер-эколог | H15: M&U, HSE | I15: AiO, mouse, keyboard | J15: AiO Lenovo V410Z | K15: 140000067/Z000098 | L15: (Забаланс) Инвентарник наклеен | N15: 1-09 второй этаж HSE | O15: YJ009HNY | P15: ="RUTL-" & RIGHT(O15,8) -> RUTL-YJ009HNY | Q15: Внесены в Passwork | R15: 2016 for home and business (BOX) | T15: Windows 10 Pro | U15: WM9FN-M2YQ7-BHFPM-WXM44-FC2KC | V15: ULTRAVNC | W15: Admin | Y15: 2018
A16: =A15+1 -> #REF! | B16: 141 | C16: Мут Александр Владимирович | D16: была модернизация/upgraded (RAM +4) | E16: Rus | F16: Mut Aleksandr | G16: Инженер по надзору за строительством | H16: GD, CONSTR | I16: AiO, mouse, keyboard | J16: AiO Lenovo V410Z | K16: 140000068/Z000120 | L16: (Забаланс) Инвентарник наклеен | N16: строительный городок | O16: YJ009HNG | P16: ="RUTL-" & RIGHT(O16,8) -> RUTL-YJ009HNG | Q16: Внесены в Passwork | R16: Microsoft Office профессиональный плюс 2016 | T16: Windows 10 Pro | V16: ULTRAVNC | W16: Admin | Y16: 2018
A17: =A16+1 -> #REF! | B17: 152 | C17: Ермакова Светлана Николаевна | D17: Модернизация не требуется/normal (no need to upgrade) | E17: Rus | F17: Ermakova Svetlana | G17: Руководитель группы | H17: Q&T, QA | I17: Laptop, mouse,bag | J17: Laptop IRBIS 17NBP4502 | K17: поставить на учет | N17: 1-09 второй этаж | O17: F2717NBP4502103188 | P17: ="RUTL-" & RIGHT(O17,8) -> RUTL-02103188 | Q17: Внесены в Passwork | R17: Libre office | T17: Windows 10 Pro | V17: ULTRAVNC / MESH | W17: No Administrator rights | X17: Кудрявцев Д. | Y17: Акт 07.10.2025 | Z17: 2024 | AA17: Норм
A18: =A17+1 -> #REF! | B18: 168 | C18: Самойленко Иван Викторович | D18: Модернизация не требуется/normal (no need to upgrade) | E18: Rus | F18: Samoylenko Ivan | G18: Начальник смены | H18: PLD,WL | I18: Laptop, mouse | J18: Laptop IRBIS 15NBP3506 | K18: 100000003637 | L18: Наклеить | N18: СКЛАД | O18: F2715NBP35060821409 | P18: ="RUTL-" & RIGHT(O18,8) -> RUTL-60821409 | Q18: Внесены в Passwork | R18: Libre office | V18: ULTRAVNC / MESH | X18: Климанов А. | Y18: Акт 13.02.2026
A19: =A18+1 -> #REF! | B19: 189 | C19: Реутов Николай Викторович | D19: Модернизация не требуется/normal (no need to upgrade) | E19: Rus | F19: Reutov Nikolay | G19: Заместитель руководителя отдела | H19: GD, LEG | I19: Laptop, mouse,bag | J19: Laptop MSI Modern 15 F1MG-800XRU | K19: поставить на учет | N19: 1-07 третий этаж | O19: C2507N0002834 | P19: ="RUTL-" & RIGHT(O19,8) -> RUTL-N0002834 | Q19: Внесены в Passwork | R19: Microsoft Office профессиональный плюс 2016 | T19: Windows 10 Pro | U19: 7D4NY-6D4V4-6BFYX-8JHWT-9KX2P | V19: ULTRAVNC | W19: No Administrator rights | X19: Летунов А. | Y19: Акт 05.12.2025 | Z19: 45989 | AA19: Стоимость ПК без НДС 59 160руб
A20: =A19+1 -> #REF! | B20: 200 | C20: Тараканов Илья Алексеевич | D20: Модернизация не требуется/normal (no need to upgrade) | E20: Rus | F20: Tarakanov Ilya | G20: Заместитель начальника цеха | H20: MD, WELD | I20: Laptop, mouse, bag | J20: Laptop MSI Modern 15 F1MG-800XRU | K20: поставить на учет | L20: Наклеить | N20: 1-02 офис цеха сварки 2 эт | O20: C2509N0008392 | P20: ="RUTL-" & RIGHT(O20,8) -> RUTL-N0008392 | Q20: Внесены в Passwork | R20: Microsoft Office профессиональный плюс 2019 | S20: M6K4N-HK7Y8-MJFXF-2HM6V-VVB86 | T20: Windows 11 Pro | U20: C8Q3W-F9N74-J944M-X7P2F-3692P | V20: ULTRAVNC / MESH | W20: No Administrator rights | X20: Кудрявцев Д. | Y20: Акт 23.03.2026 | Z20: 45985 | AA20: Стоимость ПК без НДС 59 160руб
A21: =A20+1 -> #REF! | B21: 217 | C21: Филимонов Алексей Михайлович | D21: Модернизация не требуется/normal (no need to upgrade) | E21: Rus | G21: Комплаенс-менеджер | H21: GD, LEG, ER | I21: Laptop, mouse | J21: Laptop IRBIS 15NBP3506 | K21: 100000003624 | L21: Наклеить | N21: 1-09 2 этаж | O21: F2715NBP35060821504 | P21: ="RUTL-" & RIGHT(O21,8) -> RUTL-60821504 | Q21: Внесены в Passwork | R21: Libre office | T21: Windows 11 Pro | U21: DNYKM-2BGKT-WCCHC-7M3C2-27JXC | V21: ULTRAVNC / MESH | W21: No Administrator rights | X21: Мартынов Д. | Y21: Акт 06.05.2025
A22: =A21+1 -> #REF! | B22: 223 | C22: Щербакова Елена Васильевна | D22: Модернизация не требуется/normal (no need to upgrade) | E22: Rus | F22: Sherbakova Elena | G22: Руководитель группы | H22: FD, FUND | I22: Laptop, mouse,bag | J22: Laptop MSI Modern 15 F1MG-800XRU | K22: поставить на учет | N22: 1-07 третий этаж FD, Cost | O22: C2507N0003051 | P22: ="RUTL-" & RIGHT(O22,8) -> RUTL-N0003051 | Q22: Внесены в Passwork | R22: 2016 for home and business (BOX) | T22: Windows 11 Pro | U22: N6FG2-P73MD-TRGXK-QGYGW-7FR9C | V22: ULTRAVNC / MESH | W22: No Administrator rights | X22: Летунов А. | Y22: Акт 10.12.2025 | Z22: 45989 | AA22: Стоимость ПК без НДС 59 160руб
A23: =A22+1 -> #REF! | B23: 227 | C23: Щербаков Дмитрий Юрьевич | D23: Модернизация не требуется/normal (no need to upgrade) | E23: Rus | F23: Sherbakov Dmitriy | G23: Инженер-электроник 2 категории | H23: M&U, UTL | I23: Laptop,mouse | J23: Laptop HP 250 G8 | K23: 100000002677 | L23: Наклеить | N23: 1-13 диспетчерская | O23: CND2481GQW | P23: ="RUTL-" & RIGHT(O23,8) -> RUTL-D2481GQW | Q23: Внесены в Passwork | V23: ULTRAVNC | W23: Admin | Y23: Акт 22.12.2023
A24: =A23+1 -> #REF! | B24: 239 | C24: Лейко Дарья Александровна | D24: Модернизация не требуется/normal (no need to upgrade) | E24: Rus | F24: Leyko Daria | G24: Заместитель директора цеха трансмиссии | H24: TM | I24: Laptop, mouse, bag | J24: Laptop MSI Modern 15 F1MG-800XRU | K24: поставить на учет | L24: Наклеить | N24: 1-03 офис окраски 2эт | O24: C2507N0002782 | P24: ="RUTL-" & RIGHT(O24,8) -> RUTL-N0002782 | Q24: Внесены в Passwork | R24: Professional Plus 2019 | T24: Windows 11 Pro | U24: KV9NX-4MRR2-B63VM-2JXV8-W44J2 | V24: ULTRAVNC / MESH | W24: No Administrator rights | X24: Кудрявцев Д. | Y24: Акт 27.03.2026 | Z24: 45989 | AA24: Стоимость ПК без НДС 59 160руб
A25: =A24+1 -> #REF! | B25: 243 | C25: Чучалин Роман Сергеевич | D25: Модернизация не требуется/normal (no need to upgrade) | E25: Rus | F25: Chuchalin Roman | G25: Заместитель руководителя отдела в подразделение Отдел контроля качества ТМ | H25: TM | I25: Laptop, mouse,bag | J25: Laptop IRBIS 15NBP3506 | K25: 100000003633 | L25: Наклеить | O25: F2715NBP35060820078 | P25: ="RUTL-" & RIGHT(O25,8) -> RUTL-60820078 | Q25: Внесены в Passwork | R25: Libre office | T25: Windows 10 Pro | U25: C4HD3-QN23F-VDKV2-93X3B-6VJXC | V25: ULTRAVNC / MESH | W25: No Administrator rights | X25: Фоменков В. | Y25: Акт 30.11.2024
A26: =A25+1 -> #REF! | B26: 244 | C26: Чеснокова Елена Николаевна | D26: Модернизация не требуется/normal (no need to upgrade) | E26: Rus | F26: Chesnokova Elena | G26: Лаборант | H26: CH Q&T, CH QA | I26: Laptop,mouse | J26: Laptop Dell Latitude 3450(C2) | K26: 140000014/Z000137 | L26: инвентарник ОС наклеен | M26: Внесен в ITSM AST0001707 | N26: 1-03 лаборатория окраски 1эт | O26: FPNPG22 | P26: ="RUTL-" & RIGHT(O26,8) -> RUTL-FPNPG22 | Q26: Внесены в Passwork | R26: Microsoft Office профессиональный плюс 2016 | T26: Win 7 Pro 64 | U26: 32KD2-K9CTF-M3DJT-4J3WC-733WD | V26: ULTRAVNC / MESH | W26: No Administrator rights | Y26: Акт 20.08.2018 | Z26: 42438 | AA26: БЕЗ НДС 45762,71 С НДС 54000
A27: =A26+1 -> #REF! | B27: 249 | C27: Казазаев Вадим Викторович | D27: Модернизация не требуется/normal (no need to upgrade) | E27: Rus | F27: Kazazaev Vadim | G27: Руководитель группы по переработке и утилизации отходов | H27: GD, GA, WMG | I27: Laptop, mouse | J27: Laptop Acer Extensa 15 | K27: 100000003365 | L27: наклеить | N27: 1-07 третий этаж | O27: NXEGYER00H32008CFE3400 | P27: ="RUTL-" & RIGHT(O27,8) -> RUTL-8CFE3400 | Q27: Внесены в Passwork | R27: Libre office | T27: Windows 10 Pro | V27: ULTRAVNC / MESH | W27: No Administrator rights | X27: Климанов А. | Y27: акт 18.03.2026 | Z27: 2024 | AA27: БЕЗ НДС 60440.50
A28: =A27+1 -> #REF! | B28: 258 | C28: Частников Артур Валерьевич | D28: была модернизация/upgraded (ремонт клавиатуры+SSD 256) | E28: Rus | F28: Chastnikov Artur | G28: Начальник участка | H28: PLD,ED | I28: Laptop,mouse | J28: Laptop Lenovo V510 | K28: 00000015291 | L28: инвентарник MOC наклеен | N28: 1-06 первый этаж | O28: LR0AVC0X | P28: ="RUTL-" & RIGHT(O28,8) -> RUTL-LR0AVC0X | Q28: Внесены в Passwork | U28: H82CM-NJYRT-9WYWR-8JPRQ-B98XC | V28: ULTRAVNC | Y28: Акт 22.09.2021
A29: =A28+1 -> #REF! | B29: 270 | C29: Глазов Евгений Павлович | D29: Модернизация не требуется/normal (no need to upgrade) | E29: Rus | F29: Glazov Evgeniy | G29: Инженер-электроник 2 категории | H29: M&U, UTL | I29: Laptop, mouse,bag | J29: Laptop IRBIS 17NBP4502 | K29: поставить на учет | N29: 1-13 крыло ютилити 2 эт | O29: F2717NBP4502103116 | P29: ="RUTL-" & RIGHT(O29,8) -> RUTL-02103116 | Q29: Внесены в Passwork | R29: 2019 for home and business | S29: Y77CV-RJNXD-472DD-GWBC8-29Y4G | T29: Windows 10 Pro | U29: Installed Key: VK7JG-NPHTM-C97JM-9MPGT-3V66T OEM Key: MQG4W-V8NHH-M8B6B-2382F-JHV22 | V29: ULTRAVNC / MESH | W29: Admin | X29: Кудрявцев Д. | Y29: Акт 19.09.2025 | AA29: Норм
A30: =A29+1 -> #REF! | B30: 278 | C30: Хармаев Василий Гаврилович | D30: Модернизация не требуется/normal (no need to upgrade) | E30: Rus | F30: Kharmaev Vasiliy | G30: Инженер по геометрии автомобиля 2 категории | H30: MD, WELD | I30: Laptop, mouse | J30: Laptop Lenovo V510 | K30: 00000016122 | L30: инвентарник MOC наклеен | N30: 1-02 офис цеха сварки 2 эт | O30: LR0AVC2T | P30: ="RUTL-" & RIGHT(O30,8) -> RUTL-LR0AVC2T | Q30: Внесены в Passwork | R30: SoftMaker FreeOffice 2021 | V30: ULTRAVNC / MESH | W30: No Administrator rights | X30: Климанов А. | Y30: Акт 01.12.2025
A31: =A30+1 -> #REF! | B31: 281 | C31: Дорофеев Иван | D31: Модернизация не требуется/normal (no need to upgrade) | E31: Rus | F31: Dorofeev Ivan | G31: Инженер-электроник 1 категории | H31: M&U, UTL | I31: Laptop,mouse,bag | J31: Laptop IRBIS 17NBP4502 | K31: Поставить на учет | L31: Наклеить | N31: 1-13 диспетчерская | O31: F2717NBP4502103038 | P31: ="RUTL-" & RIGHT(O31,8) -> RUTL-02103038 | Q31: Внесены в Passwork | R31: MS Office 2016/Microsoft Office профессиональный плюс 2019 — ru-ru | T31: Windows 10 Pro | U31: BTFDY-F2NTF-TY42R-4R72F-TVJXC | V31: ULTRAVNC / MESH | W31: Admin | X31: Летунов А. | Y31: Акт 17.03.2025
A32: =A31+1 -> #REF! | B32: 284 | C32: Тимченко Юлия Алексеевна | D32: Модернизация не требуется/normal (no need to upgrade) | E32: Rus | F32: Timchenko Yulia | G32: Начальник смены по качеству и технологии | H32: MD, PAINT | I32: Laptop, mouse | J32: Laptop IRBIS 15NBP3506 | K32: 100000003655 | L32: Наклеить | N32: 1-03 офис окраски 2эт | O32: F2715NBP35060820454 | P32: ="RUTL-" & RIGHT(O32,8) -> RUTL-60820454 | Q32: Внесены в Passwork | R32: Libre office | T32: Windows 10 Pro | U32: 4DN2D-GWYP7-39BJ7-FPHBC-KW3GP | V32: ULTRAVNC / MESH | W32: No Administrator rights | X32: Кудрявцев Д. | Y32: Акт от 07.12.2024
A33: =A32+1 -> #REF! | B33: 288 | C33: Макротаваров Михаил Иванович | D33: Модернизация не требуется/normal (no need to upgrade) | E33: Rus | F33: Makrotavarov Mikhail | G33: Заместитель руководителя отдела | H33: RDC,INFR | I33: Laptop,mouse | J33: Dell Vostro 7500 | K33: 10000001760 | L33: инвентарник ОС наклеен | N33: 1-07 второй этаж | O33: HCS51B3 | P33: ="RUTL-" & RIGHT(O33,8) -> RUTL-HCS51B3 | Q33: Внесены в Passwork | R33: ПАЛЕНКА Microsoft Office ????? 2021 - zh-cn | T33: Windows 10 Pro | U33: J2BNF-YDKKX-DDB37-G2JT2-TMT6P | V33: ULTRAVNC | W33: Admin | Y33: Акт 30.08.2021
A34: =A33+1 -> #REF! | B34: 293 | C34: Зажмилина Юлия Николаевна | D34: Модернизация не требуется/normal (no need to upgrade) | E34: Rus | F34: Zazhmilina Yulia | G34: Руководитель отдела | H34: MD, PM | I34: Laptop,mouse,bag | J34: Laptop MSI Modern 15 F1MG-800XRU | K34: поставить на учет | L34: Наклеить | N34: 1-09 второй этаж | O34: C2509N0008330 | P34: ="RUTL-" & RIGHT(O34,8) -> RUTL-N0008330 | Q34: Внесены в Passwork | T34: Windows 10 Pro | V34: ULTRAVNC / MESH | W34: No Administrator rights | X34: Мартынов Д. | Y34: Акт 22.01.2026
A35: =A734+1 -> #REF! | B35: 311 | C35: Ильин Дмитрий Михайлович | D35: Заменили на новый/Changed to New(no need to upgrade) | E35: Rus | F35: Ilyin Dmitriy | G35: Директор по безопасности и предотвращению рисков | H35: GD, SEC | I35: laptop,mouse, bag | J35: Laptop MSI Modern 15 F1MG-800XRU | K35: поставить на учет | N35: центральный КПП | O35: C2507N0002663 | P35: ="RUTL-" & RIGHT(O35,8) -> RUTL-N0002663 | Q35: Внесены в Passwork | T35: Windows 11 Pro | U35: NQJRW-B87PP-TYY2K-J4C72-HH66P | V35: - | W35: Admin | X35: Летунов А. | Y35: Акт 03.12.2025 | Z35: 45989 | AA35: Стоимость ПК без НДС 59 160руб
A36: =A47+1 -> #REF! | B36: 316 | C36: Тамбовцева Екатерина Юрьевна (316) | D36: Модернизация не требуется/normal (no need to upgrade) | E36: Rus | F36: Tambovtseva Ekaterina | G36: Заместитель руководителя отдела | H36: HRD, DP, HR DATA | I36: Laptop, mouse, Monitor Xiaomi A24i SN:54383/250100059569 | J36: Laptop MSI Modern 15 F1MG-800XRU | K36: поставить на учет | L36: Наклеить | N36: 1-07 третий этаж | O36: C2509N0008356 | P36: ="RUTL-" & RIGHT(O36,8) -> RUTL-N0008356 | Q36: Внесены в Passwork | R36: 2019 for home and business | T36: Windows 11 Pro | U36: 4NG8B-Y2VWK-GTCBC-6JYBR-GXX2P | V36: ULTRAVNC | W36: No Administrator rights | X36: Летунов А. | Y36: Акт 04.04.2026 | Z36: 45987 | AA36: Стоимость ПК без НДС 59 160руб
A37: =A734+1 -> #REF! | B37: 317 | C37: Белицкая Елена Александровна | D37: требуется модернизация/ need to modernisation | E37: Rus | F37: Belitskaya Elena | G37: Начальник участка | H37: PLD,ED | I37: Laptop, mouse,bag+usb ad | J37: Laptop Lenovo V110 | K37: 00000011075 | L37: инвентарник MOC наклеен | M37: Внесен в ITSM AST0002167 | N37: 1-06 второй этаж | O37: R90QN4X9 | P37: ="RUTL-" & RIGHT(O37,8) -> RUTL-R90QN4X9 | Q37: Внесены в Passwork | T37: Windows 10 Pro | U37: 6WNRY-PHJJ3-72YHR-DBDPT-HFR9C | V37: ULTRAVNC / MESH | W37: No Administrator rights | X37: Климанов А. | Y37: Акт 07.02.2026 | Z37: 43368 | AA37: БЕЗ НДС 33806,78, С НДС 39892
A38: =A37+1 -> #REF! | B38: 321 | C38: Мамкина Анастасия Викторовна | D38: Модернизация не требуется/normal (no need to upgrade) | E38: Rus | F38: Mamkina Anastasia | G38: Руководитель группы | H38: MD, PAINT | I38: Laptop,mouse | J38: Laptop IRBIS 15NBP3507 | K38: поставить на учет | L38: наклеить | N38: 1-07 Второй этаж | O38: F2715NBP35070820203 | P38: ="RUTL-" & RIGHT(O38,8) -> RUTL-70820203 | Q38: Внесены в Passwork | R38: Libre office | T38: Windows 10 Pro | U38: 94HGJ-NCRPY-GDJPY-9TCX4-PPQGP | V38: ULTRAVNC / MESH | W38: No Administrator rights | X38: Климанов А. | Y38: Акт 11.03.2026
A39: =A38+1 -> #REF! | B39: 329 | C39: Давыдов Александр Олегович ( 329 ) | D39: Модернизация не требуется/normal (no need to upgrade) | E39: Rus | F39: Davydov Alexander | G39: Заместитель директора департамента | H39: MD | I39: Laptop, mouse, bag | J39: Laptop MSI Modern 15 F1MG-800XRU | K39: поставить на учет | L39: Наклеить | N39: 1-02 офис цеха сварки 2 эт | O39: C2507N0003090 | P39: ="RUTL-" & RIGHT(O39,8) -> RUTL-N0003090 | Q39: Внесены в Passwork | R39: Libre office | T39: Windows 11 Pro | U39: GNMKF-FHVQC-4F6GR-7JVGQ-BG92P | V39: ULTRAVNC | W39: No Administrator rights | X39: Кудрявцев Д. | Y39: Акт 26.03.2026 | Z39: 45988 | AA39: Стоимость ПК без НДС 59 160руб
A40: =A39+1 -> #REF! | B40: 335 | C40: Попов Вадим Михайлович | D40: Модернизация не требуется/normal (no need to upgrade) | E40: Rus | F40: Popov Vadim | G40: Заместитель начальника цеха | H40: MD, Paint | I40: Laptop, mouse | J40: Laptop MSI Modern 15 F1MG-800XRU | K40: поставить на учет | L40: Наклеить | O40: C2507N0003035 | P40: ="RUTL-" & RIGHT(O40,8) -> RUTL-N0003035 | Q40: Внесены в Passwork | R40: 2019 for home and business | T40: Windows 11 Pro | U40: 2P9KR-RBN69-WHW89-MGFBT-H8RJ2 | V40: ULTRAVNC / MESH | W40: No Administrator rights | X40: Летунов А. | Y40: Акт 18.02.2026 | Z40: 45989 | AA40: Стоимость ПК без НДС 59 160руб
...

Sheet ПК с 2 и более владельцами
A1: № | B1: Табельный номер / Employee ID | C1: Физлицо / Owner | D1: История модернизаций, ремонтов / Modernisation, repairing history | E1: Тип домена / Domain Type | F1: Имя на английском / English name | G1: Должность / Position (Rus / Eng) | H1: Отдел / Department | I1: Комплектация / Equipment | J1: Тип и модель ПК / PC type and model | K1: Инвентарный номер / Inventory number | L1: Инвентарный номер наклеен? / Is the inventory number affixed? | M1: где хранится информация о компе | N1: Местоположение / Location | O1: Серийный номер / Serial Number | P1: Имя компьютера / PC Domain Name | Q1: TeamPass, Passwork? | R1: Тип ПО офис / Office type | S1: Ключ офиса / License key Office | T1: ОС тип / OS Type | U1: Ключ ОС / Key OS | V1: ПО удалённого управления / Remote control | W1: Админ права / Admin permissions | X1: Кто подготовил / Who installed | Y1: Дата выдачи / Issue Date | Z1: Дата покупки / Purchasing Date | AA1: Примечание / Comment
A2: 1 | B2: 6859 7841 13454 | C2: Стадольская Оксана Николаевна Долгов Ярослав Андреевич Клементьев Виталий Владимирович | D2: Модернизация не требуется/normal (no need to upgrade) | E2: Rus | F2: Stadolskaya Oksana Dolgov Yaroslav | G2: начальник участка цеха движков / Мастер 2 категории | H2: ES, ES MD, ES AS | I2: AiO, mouse, keyboard | J2: AiO Lenovo M810Z | K2: 140000062/Z000101 | L2: наклеить | N2: engine shop | O2: PC0MYXTZ | P2: ="RUTL-" & RIGHT(O2,8) -> RUTL-PC0MYXTZ | Q2: Внесены в Passwork | T2: Windows 10 Pro - 22H2/19045 | V2: ULTRAVNC / MESH | W2: No administrator rights | X2: Кудрявцев Д. / Мартынов Д. | Y2: акт 07.11.2023 / 03.09.2025 / 05.12.2025
A3: =1+A2 -> 2 | B3: 6218 10700 | C3: Дуплина Татьяна Александровна Филиппова Татьяна Денисовна | D3: Модернизация не требуется/normal (no need to upgrade) | E3: Rus | F3: Duplina Tatyana Filippova Tatyana | G3: Мастер 2 категории Оператор (промоушен на специалиста TPS) | H3: ES, ES MD, ES AS | I3: AiO, mouse, keyboard | J3: AiO Lenovo M810Z | K3: 140000172/Z000052 | L3: наклеить | N3: engine shop | O3: S4FM3331 | P3: ="RUTL-" & RIGHT(O3,8) -> RUTL-S4FM3331 | Q3: Внесены в Passwork | R3: MS Office | T3: Windows 10 Pro - 22H2/19045 | U3: R38X3-J4NJR-CRXGD-KB992-J44C2 | V3: ULTRAVNC / MESH | W3: No administrator rights | X3: Кудрявцев Д. | Y3: Акт 11.11.2025 / 19.11.2025
A4: =1+A3 -> 3 | B4: 11810 10816 | C4: Степанов Никита Алексеевич Калинин Юрий Юрьевич | D4: Модернизация не требуется/normal (no need to upgrade) | E4: Rus | F4: Stepanov Nikita Kalinin Yuri | G4: Кладовщик | H4: ES, ES PM&LS | I4: Laptop, mouse | J4: Laptop Lenovo V510 | K4: 00000011580 | L4: инвентарник MOC наклеен | N4: engine shop | O4: LR08MD5C | P4: ="RUTL-" & RIGHT(O4,8) -> RUTL-LR08MD5C | Q4: Внесены в Passwork | R4: Libre office | T4: Windows 10 Pro - 22H2/19045 | U4: GTGNK-4Y23G-TMH7C-77W3P-FX8XC | V4: ULTRAVNC / MESH | W4: No Administrator rights | X4: Кудрявцев Д. | Y4: Акт 04.06.2025 /Акт 18.06.2025
A5: =1+A4 -> 4 | B5: 7755 13475 | C5: Кадников Сергей Петрович Генг Вадим Алексеевич | D5: Модернизация не требуется/normal (no need to upgrade) | E5: Rus | F5: Kadnikov Sergey/ Geng Vadim | G5: Контролер качества/ Мастер 1 категории | H5: ES, ES Q&T, ES QTM | I5: Laptop, mouse | J5: Acer Aspire 5 A515-57-5703 | K5: поставить на учет | L5: наклеить | N5: engine shop | O5: NXKN3CD00J435010543400 | P5: ="RUTL-" & RIGHT(O5,8) -> RUTL-10543400 | Q5: Внесены в Passwork | R5: Libre office | T5: Windows 11 | U5: WBXMG-NCFQT-PB7W8-XRCXW-XW3GP | V5: ULTRAVNC / MESH | W5: No Administrator rights | X5: Мартынов Д./ Климанов А | Y5: Акт 13.08.2025/ 03.12.2025 | Z5: 45880 | AA5: БЕЗ НДС 45080, С НДС 54096
A6: =1+A5 -> 5 | B6: 12183 12098 12675 13030 13055 12905 | C6: Вышегородский Алексей Леонидович Корниенко Александр Игоревич Смирнов Дмитрий Александрович Прокопенко Сергей Юрьевич Шуев Иван Викторович | D6: была модернизация 17.04.2025/upgraded (ssd512 +8ram total 16ram | E6: Rus | F6: Vyshegorodsky Alexey Korniyenko Aleksandr Smirnov Dmitry Prokopenko Sergey Shuyev Ivan | G6: Инженер по измерениям / Инженер-технолог / Инженер-технолог / Инженер по измерениям / Инженер по измерениям | H6: ES, ES Q&T, ES QTM | I6: WorkStation,monitor(S24e-1),mouse,keyboard | J6: Компьтер Lenovo Thinkstation P520 Intel Xeon W-2104 | K6: 140000190 | L6: инвентарник ОС наклеен | N6: engine shop | O6: S4HN3450 | P6: ="RUTL-" & RIGHT(O6,8) -> RUTL-S4HN3450 | Q6: Внесены в Passwork | R6: Libre office | T6: Windows 10 Pro - 22H2/19045 | V6: ULTRAVNC / MESH | W6: No administrator rights | X6: Кудрявцев Д./ Климанов А. | Y6: Акт 12.05.2025. / 09.06.2025 / 16.09.2025/ 17.10.2025 / 06.11.2025
A7: =1+A6 -> 6 | B7: 3879 6012 6020 6076 | C7: Лялина Лилия Раисовна Балашова Ирина Анатольевна Белова Елена Бригадиренко Наталья | D7: Модернизация не требуется/normal (no need to upgrade) | E7: Rus | F7: Lyalina Lilia Balashova Irina Belova Elena Brigadirenko Natalia | G7: Диспетчеры контейнерного терминала | H7: ILD | I7: AiO, mouse, keyboard | J7: AiO Lenovo M800Z | K7: 150000023/Z000116 | L7: Наклеить | N7: 1-06 первый этаж | O7: PC0KL0L0 | P7: ="RUTL-" & RIGHT(O7,8) -> RUTL-PC0KL0L0 | Q7: Внесены в Passwork | V7: ULTRAVNC / MESH | W7: no need | X7: Кудрявцев Д. | Y7: акт 26-07-2023/акт 21-07-2023/акт 18-07-2023 Новый акт на Моторкина Д. 07.02.2025
A8: =1+A7 -> 7 | B8: 6585 6758 10645 5372 6768 6630 2659 6910 | C8: Поддубная Анна Викторовна Рыбина Наталья Владимировна Гаврильская Анастасия Алексеевна Вафина Ирина Владимировна Сушкова Ольга Владимировна Лаврищева Валерия Евгеньевна Меркулова Анастасия Александровна Сизова Ольга Валерьевна | D8: Модернизация не требуется/normal (no need to upgrade) | E8: Rus | F8: Poddubnaya Anna Viktorovna Rybina Natalya Vladimirovna Gavrilskaya Anastasia Alekseevna Vafina Irina Vladimirovna Sushkova Olga Vladimirovna Lavrishcheva Valeria Evgenievna Merkulova Anastasia Alexandrovna Sizova Olga Valerievna | G8: Специалист по складскому учету и документообороту/Warehouse and Document management specialist | H8: ILD, FPW | I8: AiO, mouse, keyboard | J8: AiO HP 200 G3 | K8: 00000021020(2) | L8: инвентарник MOC наклеен | N8: 20 сгп | O8: 8CC9164N84 | P8: ="RUTL-" & RIGHT(O8,8) -> RUTL-C9164N84 | Q8: Внесены в Passwork | R8: Microsoft Office 2007 Service Pack 3 (SP3) | T8: Windows 10 Pro - 22H2/19045 x64 | V8: ULTRAVNC | W8: ADMIN | X8: Кудрявцев Д. / Мартынов Д. | Y8: акт 15-01-2024 / / акт 29-11-2024
A9: =1+A8 -> 8 | B9: 7035 4825 10645 | C9: Жучкова Екатерина Геннадьевна Гаврильская Анастасия Медведева Татьяна | D9: модернизация прошла оперативная память добавить 8 гб | E9: Rus | F9: Zhuchkova Ekaterina / Gavrilskaya Anastasia | G9: Специалист по складскому учету и документообороту/Warehouse and Document management specialist | H9: ILD, FPW | I9: AiO, mouse, keyboard | J9: AIO HP 200 G3 | K9: 00000021020(1) | L9: инвентарник MOC наклеен | N9: 1-07_2 этаж | O9: 8CC9164N8V | P9: ="RUTL-" & RIGHT(O9,8) -> RUTL-C9164N8V | Q9: Внесены в Passwork | V9: ULTRAVNC / MESH | X9: Иванов К /Летунов А | Y9: акт 24-01-2024/21-10-2024
A10: =1+A9 -> 9 | B10: 6630 5372 2659 10645 6910 6585 6768 6758 | C10: Лаврищева Валерия Евгеньевна Вафина Ирина Владимировна Меркулова Анастасия Александровна Гаврильская Анастасия Алексеевна Сизова Ольга Валерьевна Поддубная Анна Викторовна Сушкова Ольга Владимировна Рыбина Наталья Владимировна | D10: Модернизация не требуется/normal (no need to upgrade) | E10: Rus | F10: Lavrishcheva Valeria Evgenievna Vafina Irina Vladimirovna Merkulova Anastasia Alexandrovna Gavrilskaya Anastasia Alekseevna Sizova Olga Valerievna Poddubnaya Anna Viktorovna Sushkova Olga Vladimirovna Rybina Natalya Vladimirovna | G10: Специалист по складскому учету и документообороту | H10: ILD, FPW | I10: WorkStation,monitor(S24e-1),mouse,keyboard | J10: Workstation Lenovo V530s+ отдельно монитор S24E | K10: поставить на учет | N10: 1-20 сгп новая будка | O10: YL002US0 | P10: ="RUTL-" & RIGHT(O10,8) -> RUTL-YL002US0 | Q10: Внесены в Passwork | R10: Libre office | T10: Windows 10 Pro - 22H2/19045 x64 | V10: ULTRAVNC / MESH | W10: No Administrator rights | X10: Климанов А. | Y10: Акт 19.01.2024 Акт 15.10.2025
A11: =1+A10 -> 10 | B11: 04811 2807 | C11: Белехов Николай Олегович Сьянов Антон Генадьевич | D11: была модернизация/upgraded (SSD 256) | E11: Rus | F11: Belekhov Nikolay / Syanov Anton | G11: Инженер по производственному оборудованию | H11: M&U MTC ASPC | I11: Laptop, mouse,bag | J11: Laptop Lenovo V 130 | K11: 00000019366(3) | L11: инвентарник MOC наклеен | O11: R90T947L | P11: ="RUTL-" & RIGHT(O11,8) -> RUTL-R90T947L | Q11: Внесены в Passwork | R11: Libre office | T11: Windows 10 Pro - 22H2/19045 | V11: ULTRAVNC \ MESH | W11: no need | X11: Летунов А. | Y11: акт 24-01-2025 | Z11: 43661
A12: =1+A11 -> 11 | B12: 7666 2914 2898 | C12: Савин Дмитрий Павел Стартцев Александр Агапов | D12: Модернизация не требуется/normal (no need to upgrade) | E12: Rus | F12: Pavel Startsev / Dmitry Savin / Alexander Agapov | G12: Наладчик технологического оборудования 5 категории | H12: M&U MTC ASPC | I12: Laptop, mouse,bag | J12: Laptop Lenovo T480 | K12: 140000201 | L12: инвентарник ОС наклеен | N12: 1-03 офис MU цеха окраски | O12: PF15ZDH0 | P12: ="RUTL-" & RIGHT(O12,8) -> RUTL-PF15ZDH0 | Q12: Внесены в Passwork | V12: ULTRAVNC / MESH | W12: Admin / no need | X12: Летунов А. | Y12: акт 14-03-2024
A13: =1+A12 -> 12 | B13: 9899 11269 | C13: Филатов Вячеслав Алексеевич Ким Валентин Викторович | D13: Модернизация не требуется/normal (no need to upgrade) | E13: Rus | F13: Filatov Vyacheslav / Kim Valentin | G13: Инженер по производственному оборудованию / Production Equipment Engineer | H13: M&U MTC ASPC | I13: WorkStation+monitor lenovo T24I | J13: Workstation Lenovo ThinkStation P 520 | K13: 140000188 | L13: инвентарник ОС наклеен | N13: 1-04 офис MU цеха сборки | O13: S4HN3478 | P13: ="RUTL-" & RIGHT(O13,8) -> RUTL-S4HN3478 | Q13: Внесены в Passwork | R13: 2016 for home and business (BOX) | T13: Windows 10 Pro - 22H2/19045 x64 | V13: ULTRAVNC / MESH | W13: Admin / no need | X13: Кудрявцев Д. | Y13: Акт 07.11.2024 / Акт 30.01.2025
A14: =1+A13 -> 13 | B14: 9735 738 | C14: Волкова София Александровна Ельцов Андрей | D14: Модернизация не требуется/normal (no need to upgrade) | E14: Rus | F14: Volkova Sofia | G14: Диспетчер | H14: M&U UTL | I14: AiO, mouse, keyboard | J14: AiO Lenovo M800Z | K14: 150000026/Z000001 | L14: наклеить | N14: 1-07 3 этаж | O14: PC0KDWEW | P14: ="RUTL-" & RIGHT(O14,8) -> RUTL-PC0KDWEW | Q14: Внесены в Passwork | R14: Libre office | T14: Windows 10 Pro - 22H2/19045 | V14: ULTRAVNC / MESH | W14: No Administrator rights | X14: Летунов А. / Мартынов Д. | Y14: Акт 07,12,2024
A15: =1+A14 -> 14 | B15: ??? проверить на активные уч записи | C15: Екатерина Чуванкова Казакова Анна Хусейнова Карина Анваровна | D15: требуется замена жесткого диска/need to modernisation(replacement to hard disk) | E15: Rus | F15: Chuvankova Ekaterina /Khuseynova Karina | G15: Наладчик технологического оборудования 2 категории/ Наладчик технологического 1 категории | H15: M&U, ESCP | I15: AiO, mouse, keyboard | J15: AiO Lenovo M810Z | K15: 140000168/Z000085 | L15: Наклеить | N15: У MU в цехе окраски склад МЮ 1 эт | O15: S4FM3439 | P15: ="RUTL-" & RIGHT(O15,8) -> RUTL-S4FM3439 | Q15: Внесены в Passwork | R15: 2016 for home and business (BOX) | V15: ULTRAVNC / MESH | W15: no need | X15: Климанов А./ Мартынов Д. / Летунов А. | Y15: акт 07-11-2024 / 12,12,2024/24.11..2025
A16: =1+A15 -> 15 | B16: 9454 / 5150 | C16: Пацук Евгений Викторович Денисов Олег Вячеславович | D16: Модернизация не требуется/normal (no need to upgrade) | E16: Rus | F16: Patsuk Evgeniy / Denisov Oleg | G16: Мастер-механик по ремонту специальной дорожной техники | H16: M&U, FAC | I16: Laptop, mouse | J16: Laptop Lenovo Thinkpad L580 | K16: 14000157/Z000047 | L16: Наклеить | N16: 1-13 | O16: PF12TW42 | P16: ="RUTL-" & RIGHT(O16,8) -> RUTL-PF12TW42 | Q16: Внесены в Passwork | R16: Libre office | T16: Windows 10 Pro - 22H2/19045 x64 | U16: KTNFX-XDQTR-DWXF4-CQYJQ-9766P | V16: ULTRAVNC / MESH | W16: No Administrator rights | X16: Мартынов Д. | Y16: Акт 26.11.2025 | Z16: 43236 | AA16: БЕЗ НДС 41754,78, С НДС 50920,47
A17: =1+A16 -> 16 | B17: 11353/ 2494 | C17: Сайков Максим Владимирович/ Макаров Александр Владимирович | D17: Модернизация не требуется/normal (no need to upgrade) | E17: Rus | F17: Saykov Maxim/ Makarov alexander | G17: Начальник смены технического обслуживания оборудования 1 категории | H17: M&U, MTC ES | I17: Laptop, mouse | J17: Laptop IRBIS 15NBP3507 | K17: поставить на учет | L17: Наклеить | N17: engine shop | O17: F2715NBP35070821672 | P17: ="RUTL-" & RIGHT(O17,8) -> RUTL-70821672 | Q17: Внесены в Passwork | R17: Libre office | T17: Windows 11 | V17: ULTRAVNC / MESH | W17: No Administrator rights | X17: Мартынов Д./ Климанов А | Y17: Акт 28.03.2025/ 03.12.2025
A18: =1+A17 -> 17 | B18: 11172 / 13527 | C18: Маркаров Григорий Аванесович Стуканов Дмитрий Олегович | D18: Модернизация не требуется/normal (no need to upgrade) | E18: Rus | F18: Markarov Grigory | G18: Инженер по производственному оборудованию | H18: M&U, MTC ES | I18: Laptop,mouse+Lan-USB | J18: Laptop Lenovo V15 G1+Lan-USB | K18: 100000001646 | L18: Наклеить | O18: PF2VSVTT | P18: ="RUTL-" & RIGHT(O18,8) -> RUTL-PF2VSVTT | Q18: Внесены в Passwork | R18: Libre office | T18: MS Windows 10 Prof | V18: ULTRAVNC / MESH | X18: Климанов А. | Y18: Акт 03.02.2025
A19: =1+A18 -> 18 | B19: 13532 / 14580 | C19: Баранников Михаил Юрьевич / Уткин Александр | D19: Модернизация не требуется/normal (no need to upgrade) | E19: Rus | F19: Barannikov Mikhail / Utkin Alexander | G19: Инженер-механик 1 категории | H19: M&U, MTC ES | I19: Laptop, mouse | J19: Laptop IRBIS 15NBP3506 | K19: 100000003606 | L19: наклеить | O19: F2715NBP35060821908 | P19: ="RUTL-" & RIGHT(O19,8) -> RUTL-60821908 | Q19: Внесены в Passwork | R19: Libre office | T19: Windows 10 Pro - 22H2/19045 x63 | U19: P83YN-KPWY2-WJDW6-M8W9G-722KC | V19: ULTRAVNC \ MESH | W19: No Administrator rights | X19: Климанов А / Мартынов Д. | Y19: Акт 11.12.2025 / 14.02.2026
A20: =1+A19 -> 19 | B20: 6574 13330 | C20: Чутов Иван Андреевич Тиссен Елена Николаевна | D20: Модернизация не требуется/normal (no need to upgrade) | E20: Rus | F20: Chutov Ivan Tissen Elena | G20: Начальник участка обслуживания оборудования Наладчик технологического оборудования 1 категории | H20: M&U, MTC ES / M&U, ESCP | I20: Laptop, mouse | J20: Laptop Acer Extensa 15 | K20: 100000003346 | L20: наклеить | N20: 1-03 офис окраски 2эт | O20: NXEGYER00H320086173400 | P20: ="RUTL-" & RIGHT(O20,8) -> RUTL-86173400 | Q20: Внесены в Passwork | R20: Libre office | T20: Windows 10 Pro - 22H2/19045 x64 | U20: C99VN-XGR47-JGGHW-9M8DK-Y7WGG | V20: ULTRAVNC / MESH | W20: Admin | X20: Иванов К. Кудрявцев Д. | Y20: Акт 17.05.2024 20.11.2025 | Z20: 45385 | AA20: БЕЗ НДС 60440.50
A21: =1+A20 -> 20 | B21: 629 / 7606 | C21: Карпенко Григорий Александрович / Судоргин Андрей Николаевич | D21: была модернизация/upgraded (SSD)+ram | E21: Rus | F21: Karpenko Grigoriy / Sudorgin Andrey | G21: Начальник участка / Мастер 2 категории | H21: MD, AS | I21: Laptop, mouse | J21: Laptop Lenovo V110 | K21: 00000010779 | L21: инвентарник MOC наклеен | M21: Внесен в ITSM AST0001453 | N21: 1-07 четвертый этаж | O21: R90QFPZM | P21: ="RUTL-" & RIGHT(O21,8) -> RUTL-R90QFPZM | Q21: Внесены в Passwork | R21: 2019 for home and business | T21: Windows 10 Pro - 22H2/19045 | U21: QNYK7-PG6FK-BT8DX-7T62C-FX8XC | V21: ULTRAVNC / MESH | W21: No Administrator rights | X21: Кудрявцев Д. | Y21: Акт 28.03.2025 / 25.09.2025
A22: =1+A21 -> 21 | B22: 0000000758/0000002518 | C22: Бердник Евгений Игоревич/Грушихин Денис | D22: была модернизация/upgraded (SSD 256)/ Модернизация была добавлено 4 ГБ оперативной памяти | E22: Rus | F22: Berdnik Evgeniy/Gruishikhin | G22: Начальники участка Chassis1 | H22: MD, AS | I22: Laptop, mouse | J22: Laptop Lenovo V110 | K22: 00000010781 | L22: инвентарник MOC наклеен | M22: Внесен в ITSM AST0001575 | N22: 1-04 офис цеха сборки | O22: R90QFQ06 | P22: ="RUTL-" & RIGHT(O22,8) -> RUTL-R90QFQ06 | Q22: Внесены в Passwork | R22: Libre office | T22: Windows 10 Pro - 22H2/19045 | V22: ULTRAVNC / MESH | W22: No Administrator rights | X22: Мартынов Д. | Y22: Акт 17.12.2025 | Z22: 43325 | AA22: БЕЗ НДС 30247.46 С НДС 35692.00
A23: =#REF!+1 -> #REF! | B23: - | C23: Final 2 Попов Максим Олегович , Федосова/Чирков Роман Валерьевич 3968 | D23: Подвергся вандализму | E23: Rus | F23: Chirkov Roman/Fedosova | G23: Инженер по электрике автомобиля 3 категории/Мастер 2 категории | H23: MD, AS | I23: Laptop, mouse + Keyboard | J23: Laptop Lenovo V 130 | K23: 00000019366(18) | L23: инвентарник MOC наклеен | N23: 1-04 офис цеха сборки | O23: R90T9486 | P23: ="RUTL-" & RIGHT(O23,8) -> RUTL-R90T9486 | Q23: Внесены в Passwork | V23: ULTRAVNC / MESH | W23: No Administrator rights | X23: Мартынов Д./Климанов А. | Y23: Акт 17.12.2025/19.03.2026 | Z23: 43661
A24: =1+'ПК с 2 и более владельцами'!A23 -> #REF! | B24: 594 4030 2293 1138 5494 14180 | C24: Попов Максим Владимирович Болясов Михаил Владимирович Боенков Сергей Игоревич Леонова Ирина Сергеевна Крутая Анастасия Андреевна Ерещенко Елизавета Дмитриевна | D24: была модернизация/upgraded (SSD)+ram | E24: Rus | F24: Popov Maksim Bolyasov Mikhail Boyenkov Sergey Leonova Irina Krutaya Anastasiya | G24: Начальник участка Мастер по ремонту 1 категории Мастер по ремонту 1 категории Слесарь по ремонту автомобилей 2 категории Оператор | H24: MD, AS | I24: Laptop, mouse,bag | J24: Laptop Lenovo V510 | K24: 00000015285 | L24: инвентарник MOC наклеен | N24: 1-04 (Фин.инспекция) участок СГП | O24: LR0AVC21 | P24: ="RUTL-" & RIGHT(O24,8) -> RUTL-LR0AVC21 | Q24: Внесены в Passwork | R24: Libre office | T24: Windows 10 Pro - 22H2/19045 | V24: ULTRAVNC / MESH | W24: No administrator rights | X24: Кудрявцев Д. /Летунов А. / Кудрявцев Д. / Мартынов Д / Летунов А. | Y24: Акт от 15.11.2024 /акт 15.04.2025 / 25.09.2025 / 24.10.2025 / 18.02.2026 / 19.03.2026
A25: =1+A24 -> #REF! | C25: Бирькина Анна / Лесников Егор Юрьевич | D25: была модернизация/upgraded (SSD 256)/ Модернизация была добавлено 4 ГБ оперативной памяти | E25: Rus | F25: Birkina Anna/Lesnikov Egor | G25: Мастер 2 категории линия Trim1 | H25: MD, AS | I25: Laptop, mouse,bag | J25: Laptop Lenovo V510 | K25: 00000015284 | L25: инвентарник MOC наклеен | N25: 1-04 офис цеха сборки | O25: LR0AVC25 | P25: ="RUTL-" & RIGHT(O25,8) -> RUTL-LR0AVC25 | Q25: Внесены в Passwork | V25: ULTRAVNC / MESH | W25: No Administrator rights | X25: Мартынов Д. | Y25: Акт 17.12.2025
A26: =1+A25 -> #REF! | B26: 834/809/4622/605 | C26: Романов Дмитрий Сергеевич/ Буенок Сергей Николаевич/Стародубов Кирилл Сергеевич/Коробков Андрей Евгеньевич | D26: Модернизация не требуется/normal (no need to upgrade) | E26: Rus | F26: Romanov Dmitry/ Buenok Sergey/Starodubov Kirill/Korobkov Andrey | G26: Начальник участка, Мастер по ремонту 1 категории/ Мастер по ремонту 1 категории | H26: MD, AS | I26: Laptop, mouse,bag | J26: Laptop Acer Extensa 15 | K26: 100000003342 | L26: наклеить | N26: 1-04 офис цеха сборки | O26: NXEGYER00H320089B63400 | P26: ="RUTL-" & RIGHT(O26,8) -> RUTL-89B63400 | Q26: Внесены в Passwork | R26: Libre office | T26: Windows 10 Pro - 22H2/19045 | V26: ULTRAVNC / MESH | W26: No Administrator rights | X26: Мартынов Д./Климанов А. | Y26: Акт 07.05.2025/ 19.12.2025/ 16.02.2026 | Z26: 2024 | AA26: БЕЗ НДС 60440.50
A27: =1+A26 -> #REF! | B27: 7494 | C27: Петрищев Василий Викторович Жданов Александр Сергеевич ( не пришел за учеткой) | D27: Модернизация не требуется/normal (no need to upgrade) | E27: Rus | F27: Petrishchev Vasily / Zhdanov Alexander | G27: Инженер-технолог 1 категории / Мастер 1 категории | H27: MD, AS | I27: Laptop, mouse | J27: Laptop Acer Extensa 15 | K27: 100000003351 | L27: наклеить | O27: NXEGYER00H32008ABE3400 | P27: ="RUTL-" & RIGHT(O27,8) -> RUTL-8ABE3400 | Q27: Внесены в Passwork | V27: ULTRAVNC | X27: Летунов А. / Мартынов Д. | Y27: Акт 31.05.2024 / 09.07.2025 | Z27: 2024 | AA27: БЕЗ НДС 60440.50
A28: =1+A27 -> #REF! | B28: 1656 3162 | C28: Поляков Евгений Вадимович Дубровин Сергей Валерьевич | D28: Модернизация не требуется/normal (no need to upgrade) | E28: Rus | F28: Polyakov Evgeniy / Dubrovin Sergey | G28: Технолог 3 категории / Оператор | H28: MD, AS | I28: Laptop, mouse | J28: Acer Aspire Lite 15 AL15-41 | K28: поставить на учет | L28: Наклеить | N28: 1-04 офис цеха сборки | O28: UN31ZSI04F533024740700 | P28: ="RUTL-" & RIGHT(O28,8) -> RUTL-24740700 | Q28: Внесены в Passwork | T28: Windows 11 | V28: ULTRAVNC / MESH | W28: No Administrator rights | X28: Климанов А. | Y28: Акт 05.12.2025/05.12.2025 | Z28: 45975 | AA28: БЕЗ НДС 36790 с НДС -
A29: =1+A28 -> #REF! | B29: 340 1595 | C29: Рольгейзер Николай Николаевич Собаченков Михаил Геннадьевич | D29: Модернизация не требуется/normal (no need to upgrade) | E29: Rus | F29: Rolgeyzer Nikolay/Sobachenkov Mikhail | G29: Инженер-технолог 1 категории | H29: MD, AS | I29: Laptop, mouse | J29: Acer Aspire Lite 15 AL15-41 | K29: поставить на учет | L29: Наклеить | N29: 1-04 офис цеха сборки | O29: UN31ZSI04F533024CD0700 | P29: ="RUTL-" & RIGHT(O29,8) -> RUTL-24CD0700 | Q29: Внесены в Passwork | R29: Libre office | T29: Windows 11 Pro | U29: VK7JG-NPHTM-C97JM-9MPGT-3V66T | V29: ULTRAVNC / MESH | W29: No Administrator rights | X29: Кудрявцев Д./ Климанов А. | Y29: Акт 10.12.2025/11.12.2025 | Z29: 45975 | AA29: БЕЗ НДС 36790 с НДС -
A30: =1+A29 -> #REF! | B30: 1420 1355 6433 2236 7414 | C30: Трифонов Иван Михайлович Хуснутдинов Рустам Викторович Васюнин Денис Владимирович Хабибулин Дмитрий Тахирович Горин Иван Андреевич | D30: была модернизация/upgraded (SSD 256)/ Модернизация была добавлено 4 ГБ оперативной памяти | E30: Rus | F30: Trifonov Ivan Khusnutdinov Rustam Gorin Ivan | G30: Начальники участка Door Line Мастер 2 категории Мастер 2 категории | H30: MD, AS | I30: Laptop, mouse | J30: Laptop Lenovo V510 | K30: 00000016134 | L30: инвентарник MOC наклеен | N30: 1-04 офис цеха сборки | O30: LR0AVC2H | P30: ="RUTL-" & RIGHT(O30,8) -> RUTL-LR0AVC2H | Q30: Внесены в Passwork | R30: Libre office | T30: Windows 10 Pro - 22H2/19045 | V30: ULTRAVNC / MESH | W30: No Administrator rights | X30: Мартынов Д | Y30: Акт 17.12.2025 / 18.02.2026 / 24.02.2026
A31: =1+A30 -> #REF! | C31: Викторов Иван /Фирсов Валерий | D31: была модернизация/upgraded/была добавлено 8 ГБ оперативной памяти | E31: Rus | G31: Начальники участка Engine | H31: MD, AS | I31: Laptop, mouse | J31: Laptop Lenovo L340 | K31: 00000022303(7) | L31: инвентарник МОС наклеен | N31: 1-04 офис цеха сборки | O31: PF14SQHW | P31: ="RUTL-" & RIGHT(O31,8) -> RUTL-PF14SQHW | Q31: Внесены в Passwork | U31: По свински | Y31: Акт 10.02.2020
A32: =1+A31 -> #REF! | B32: 11821/ 10171 | C32: Шведов Даниил Игоревич Подгорнев Александр Владиславович | D32: Модернизация не требуется/normal (no need to upgrade) | E32: Rus | F32: Shvedov Daniil/ Podgornev Alexander | G32: Начальник участка / Мастер 2 категории | H32: MD, AS | I32: Laptop, mouse | J32: Laptop Dell Latitude 3450(C2) | K32: 140000012/Z000139 | L32: инвентарник ОС наклеен | M32: Внесен в ITSM AST0001705 | N32: 1-04 офис цеха сборки | O32: 2QNPG22 | P32: ="RUTL-" & RIGHT(O32,8) -> RUTL-2QNPG22 | Q32: Внесены в Passwork | R32: Libre office | T32: Windows 10 Pro - 22H2/19045 | U32: XNRBW-3Q2VH-VGFH2-TCBFV-G6MD2 | V32: ULTRAVNC / MESH | W32: No Administrator rights | X32: Кудрявцев Д./ Климанов А | Y32: Акт 13.03.2025/ 25.12.2025 | Z32: 42438
A33: =1+A32 -> #REF! | C33: Попов Павел 0000002187/ Петров 0000001837 | D33: Модернизация не требуется/normal (no need to upgrade) | E33: Rus | H33: MD, AS | I33: Laptop, mouse | J33: Laptop Lenovo ThinkPad EDGE E560(C2) | K33: 140000040/Z000019 | L33: Наклеить | N33: 1-04 офис цеха сборки | O33: PF0L9GF3 | P33: ="RUTL-" & RIGHT(O33,8) -> RUTL-PF0L9GF3 | Q33: Внесены в Passwork | R33: Libre office | T33: Windows 10 Pro - 22H2/19045 | U33: Installed Key: VK7JG-NPHTM-C97JM-9MPGT-3V66T OEM Key: B2WJH-PNYTH-RQHYP-22YK8-F3K2P | V33: ULTRAVNC / MESH | W33: No administrator rights | X33: Кудрявцев Д. | Y33: Акт от 03.04.2025
A34: =1+A33 -> #REF! | B34: 2024 6389 | C34: Муллоева Анастасия Алексеевна Бабкин Евгений Сергеевич | D34: Модернизация не требуется/normal (no need to upgrade) | E34: Rus | F34: Mulloeva Anastasia Babkin Evgeny | G34: Специалист TPS Инженер-технолог 1 категории | H34: MD, AS | I34: Laptop, mouse | J34: Laptop Acer Extensa 15 | K34: 100000003336 | L34: Наклеить | N34: 1-04 офис цеха сборки | O34: NXEGYER00H320089263400 | P34: ="RUTL-" & RIGHT(O34,8) -> RUTL-89263400 | Q34: Внесены в Passwork | T34: Windows 10 Pro - 22H2/19045 | U34: 2P9NF-YQJKV-CH6KD-HTXVC-J44C2 | V34: ULTRAVNC / MESH | W34: No Administrator rights | X34: Кудрявцев Д. | Y34: Акт 05.07.2024 Акт 30.01.2026 | Z34: 2024 | AA34: БЕЗ НДС 60440.50
A35: =1+A34 -> #REF! | C35: Прохоров Максим /Горлачев Антон | D35: была модернизация/upgraded (SSD 256) | E35: Rus | G35: Начальники участка Final 1 | H35: MD, AS | I35: Laptop, mouse,bag | J35: Laptop Lenovo V110 | K35: 00000011058 | L35: инвентарник MOC наклеен | N35: 1-07 третий этаж | O35: R90QN4VW | P35: ="RUTL-" & RIGHT(O35,8) -> RUTL-R90QN4VW | Q35: Внесены в Passwork | U35: 4XHTB-VNXWT-QCF3R-M4D89-DYH22 | V35: ULTRAVNC / MESH | W35: No Administrator rights | X35: Мартынов Д. | Y35: Акт 18.12.2025 | Z35: 43368 | AA35: БЕЗ НДС 33806,78, С НДС 39892
A36: =1+A35 -> #REF! | B36: 774/7997/7535/841 | C36: Сысоев Станислав Викторович/ Блок Александр Александрович/Баранюк Руслан Иванович/ Васильев Василий Сергеевич | D36: Модернизация не требуется/normal (no need to upgrade) | E36: Rus | F36: Sysoev Stanislav/ Blok Alexander/ Baranyuk Rusla/ Vasilyev Vasily | G36: Начальник участка/ мастер 1 категории/Мастер 1 категории/ Начальник участка | H36: MD, AS | I36: Laptop,mouse+Lan-USB | J36: Laptop Lenovo V15 G1+Lan-USB | K36: 100000001625 | L36: Наклеить | M36: Внесен в ITSM AST0000875 | N36: 1-04 линия двигателей | O36: PF2TM25W | P36: ="RUTL-" & RIGHT(O36,8) -> RUTL-PF2TM25W | Q36: Внесены в Passwork | V36: ULTRAVNC | X36: Климанов А. | Y36: Акт 19.07.2022/ 25.09.25/ 23.12.25/ 24.12.25
A37: =1+A36 -> #REF! | B37: 13491/14582 | C37: Шуршиков Роман Сергеевич/ Анашкина Алина Витальевна | D37: Модернизация не требуется/normal (no need to upgrade) | E37: Rus | F37: Shurshikov Roman/ Anashkina Alina | G37: Технолог 1 категории | H37: MD, AS | I37: Laptop, mouse | J37: Laptop IRBIS 15NBP3507 | K37: поставить на учет | L37: Наклеить | N37: 1-04 офис цеха сборки | O37: F2715NBP35070820586 | P37: ="RUTL-" & RIGHT(O37,8) -> RUTL-70820586 | Q37: Внесены в Passwork | R37: Libre office | T37: Windows 10 Pro - 22H2/19045 | V37: ULTRAVNC / MESH | W37: No Administrator rights | X37: Кудрявцев Д. | Y37: Акт 27.03.2025 Акт 25.09.2025 Акт 11.12.2025
A38: =1+'ПК с 1 владельцем'!A687 -> #REF! | B38: 11265 13513 | C38: Костикова Ирина Александровна Попова Анастасия Андреевна | D38: Модернизация не требуется/normal (no need to upgrade) | E38: Rus | F38: kostikova irina / Popova Anastasia | G38: Специалист по качеству Оператор | H38: MD, AS | I38: Laptop, mouse | J38: Laptop Lenovo L340 | K38: 10000001780 | L38: Наклеить | N38: 45748 | O38: PF1SL81M | P38: ="RUTL-" & RIGHT(O38,8) -> RUTL-PF1SL81M | Q38: Внесены в Passwork | R38: Libre office | T38: Windows 10 Pro - 22H2/19045 | V38: ULTRAVNC / MESH | X38: Климанов А. / Мартынов Д. | Y38: Акт 01.09.2025 / 27.02.2026
A39: =1+A38 -> #REF! | B39: 4407 / 14856 | C39: Рязанов Максим Александрович / Фатюшин Александр Владимирович | D39: Модернизация не требуется/normal (no need to upgrade) ОЗУ 12 SSD 256 | E39: Rus | F39: Ryazanov Maxim / Fatyushin Alexander | G39: Начальник участка | H39: MD, AS | I39: Laptop, mouse | J39: Laptop Lenovo V110 | K39: 00000011070 | L39: инвентарник MOC наклеен | M39: Внесен в ITSM AST0002160 | O39: R90QN4VJ | P39: ="RUTL-" & RIGHT(O39,8) -> RUTL-R90QN4VJ | Q39: Внесены в Passwork | T39: Windows 10 Pro | U39: HK7WV-VN4Q8-RH7GX-XDR27-GCQGP | V39: ULTRAVNC / MESH | W39: No Administrator rights | X39: Летунов А. / Мартынов Д. | Y39: Акт 10.03.2026 | Z39: 43368 | AA39: БЕЗ НДС 33806,78, С НДС 39892
A40: ='ПК с 1 владельцем'!A625+1 -> 13 | B40: - | C40: Векшина Анастасия Красюк Елена Викторовна 11248 | D40: Модернизация не требуется/normal (no need to upgrade) | E40: Rus | F40: Vekshina Anastasia/ Krasyuk Elena | G40: Диспетчер производства | H40: MD, AS | I40: AiO, mouse, keyboard | J40: AiO Lenovo S400Z | K40: 150000011/Z000010 | L40: Наклеить | N40: 1-04 офис цеха сборки | O40: P901FSLH | P40: ="RUTL-" & RIGHT(O40,8) -> RUTL-P901FSLH | Q40: Внесены в Passwork | R40: 2016 for home and business (BOX) | V40: ULTRAVNC / MESH | W40: no need | X40: Летунов А./Климанов А. | Y40: акт 15.11.2024/Акт от 13.03.2026
...

Sheet Технические ПК
A1: # | B1: Technical_PC
B2: Табельный номер / Employee ID | C2: Физлицо / Owner | D2: История модернизаций, ремонтов / Modernisation, repairing history | E2: Тип домена / Domain Type | F2: Имя на английском / English name | G2: Должность / Position (Rus / Eng) | H2: Отдел / Department | I2: Комплектация / Equipment | J2: Тип и модель ПК / PC type and model | K2: Инвентарный номер / Inventory number | L2: Инвентарный номер наклеен? / Is the inventory number affixed? | M2: где хранится информация о компе | N2: Местоположение / Location | O2: Серийный номер / Serial Number | P2: Имя компьютера / PC Domain Name | Q2: TeamPass, Passwork? | R2: Тип ПО офис / Office type | S2: Ключ офиса / License key Office | T2: ОС тип / OS Type | U2: Ключ ОС / Key OS | V2: ПО удалённого управления / Remote control | W2: Админ права / Admin permissions | X2: Кто подготовил / Who installed | Y2: Дата выдачи / Issue Date | Z2: Дата покупки / Purchasing Date | AA2: Примечание / Comment
A3: 1 | C3: Весовая Акт Казазаев 19-09-2025 | D3: была модернизация/upgraded (SSD 480 +RAM8) | E3: Rus | H3: GA_для весового контроля | I3: AiO, -мышь свою оставил (личная), keyboard | J3: AiO Lenovo S400Z | K3: 150000006/Z000012 | L3: Наклеить | N3: СКЛАД | O3: P901FSPN | P3: ="RUTL-" & RIGHT(O3,8) -> RUTL-P901FSPN | X3: Летунов А. | Y3: Акт 18,09,2025 | AA3: Норм
A4: 2 | C4: Куан Хэн акт 08-02-2019 | D4: очень старый /old(2015-2017 г) | E4: Rus | H4: GA_для комендантов общежития | I4: Workstation, Monitor(Lenovo 19" LT 1952p Black/240000014-0002)mouse, keyboard | J4: WorkStation Lenovo ThinkCenter M73(24000014) | K4: 00000000315 | L4: Наклеить | N4: local acc Dormitory.105-106 | O4: PC017TGV | P4: ="RUTL-" & RIGHT(O4,8) -> RUTL-PC017TGV
A5: 3 | C5: Мамед Г акт 07-08-2024 | D5: очень старый /old(2015-2017 г) | E5: Rus | H5: GA_для комендантов общежития | I5: WorkStation,monitor(20994),mouse,keyboard | J5: WorkStation Lenovo M93p | K5: 100000001343(0000009138(1)) | L5: Наклеить | N5: local acc Dormitory.105-106 | O5: PBP3W0G | P5: ="RUTL-" & RIGHT(O5,8) -> RUTL-PBP3W0G
A6: 4 | C6: Sec_КПП Огаревка( акт 13-02-2024 Ильин Д) | D6: требуется модернизация/ need to modernisation | H6: GD, SEC, SG | I6: Laptop,mouse | J6: Laptop Lenovo x240 | K6: поставить на учет | L6: MOSCOW | N6: 1-02 офис MU цеха сварки | O6: PF0095LY | P6: ="RUTL-" & RIGHT(O6,8) -> RUTL-PF0095LY | X6: Летунов А. | Y6: Акт 13-02-24 | Z6: 2013
A7: 5 | C7: технический компьютер с кпп | D7: Модернизация не требуется/normal (no need to upgrade) | H7: GD, SEC, SG | I7: WorkStation,monitor,mouse,keyboard | J7: Workstation Lenovo V530s+ отдельно монитор | K7: не на балансе | L7: Наклеить | N7: КПП | O7: YL002WQK | P7: ="RUTL-" & RIGHT(O7,8) -> RUTL-YL002WQK | U7: VMRJN-B8RC7-QBJMM-GVM8D-QRR9C | V7: ULTRAVNC
A8: 6 | C8: для электронных птс СОБОЛЬ (Болясова) СГП ЭПТС EPTS | D8: need check | G8: Специалист по выпуску электронного паспорта | H8: GD,FPW (соболь) | I8: WorkStation,monitor,mouse,keyboard | J8: Workstation Lenovo V530+ отдельно монитор Т24м | K8: 140000214 | L8: инвентарник ОС наклеен | N8: 45839 | O8: YL002URP | P8: ="RUTL-" & RIGHT(O8,8) -> RUTL-YL002URP
A9: 7 | C9: для электронных птс СОБОЛЬ (Акт на Аверьянову 12-08-2024) СГП EPTS ЭПТС | D9: need check | G9: Специалист по выпуску электронного паспорта | H9: GD,FPW (соболь) | I9: WorkStation,monitor,mouse,keyboard | J9: Workstation Lenovo V530s+ отдельно монитор S24E | K9: поставить на учет | L9: - | N9: 45839 | O9: YL002US3 | P9: ="RUTL-" & RIGHT(O9,8) -> RUTL-YL002US3
A10: 8 | C10: для электронных птс СОБОЛЬ (Акт Рязанцев К. 12-01-2022 г) Петрова СГП EPTS ЭПТС | D10: need check | G10: Специалист по выпуску электронного паспорта | H10: GD,FPW (соболь) | I10: WorkStation,monitor,mouse,keyboard | J10: Workstation Lenovo V530+ отдельно монитор Т24м | K10: 140000213 | L10: инвентарник ОС наклеен | N10: 45839 | O10: YL003MHN | P10: ="RUTL-" & RIGHT(O10,8) -> RUTL-YL003MHN
A11: 9 | C11: для электронных птс СОБОЛЬ Корнева Светлана Евгеньевна СГП EPTS ЭПТС | D11: need check | G11: Специалист по выпуску электронного паспорта | H11: GD,FPW (соболь) | I11: WorkStation,monitor,mouse,keyboard | J11: Workstation Lenovo V530s+ отдельно монитор Т24I | K11: 100000001345 | L11: Наклеить | N11: 1-06 первый этаж | O11: YL00STYS | P11: ="RUTL-" & RIGHT(O11,8) -> RUTL-YL00STYS | Q11: Внесены в Passwork | R11: Microsoft Office профессиональный плюс 2016 | T11: Windows 10 Pro - 22H2/19048 | V11: ULTRAVNC / MESH | W11: No Administrator rights | X11: Климанов А. | Y11: Акт 07.02.2026
A12: 10 | C12: HR_Training_PC | D12: need check | H12: HR Training | I12: Laptop | J12: Ноутбук Lenovo V130 | K12: 00000022357 | L12: инвентарник MOC наклеен | N12: HR_Room 303 | O12: R90TY3EF | P12: ="RUTL-" & RIGHT(O12,8) -> RUTL-R90TY3EF
A13: 10 | C13: HR_Training_PC | D13: need check | H13: HR Training | I13: Laptop,mouse | J13: Laptop Lenovo V110 | K13: 00000011057 | L13: инвентарник MOC наклеен | N13: HR_Room 303 | O13: R90QN4WF | P13: ="RUTL-" & RIGHT(O13,8) -> RUTL-R90QN4WF | Q13: Внесены в Passwork | R13: 2019 for home and business | S13: RGBN3-7RY3T-236WV-8MQGK-H6FRG | T13: Windows 10 Pro | U13: TWVTN-Y6PFT-WHX9Q-R3FJ9-TF4C2 | V13: ULTRAVNC / MESH | W13: No Administrator rights | X13: Лктунов А. | Y13: Акт 03.04.2026 | Z13: 43368 | AA13: БЕЗ НДС 33806,78, С НДС 39892
A14: 12 | C14: HSE_Training_PC (Акт на Волкову К.) | D14: Модернизация не требуется/normal (no need to upgrade) SSD 256 озу 8 | H14: hse_Training | I14: Laptop,mouse | J14: Laptop Lenovo V110 | K14: 00000010768 | L14: Наклеить | N14: hse обучение | O14: R90QFPY7 | P14: ="RUTL-" & RIGHT(O14,8) -> RUTL-R90QFPY7 | U14: RPDWY-7NXM3-PFC7K-FGDXQ-Y4G6P
A15: 11 | C15: Шустова Полина Сергеевна (Используется для атестации) | D15: была модернизация/upgraded (SSD 480 +RAM8) | H15: hse_Training ( для атестации) | I15: AiO, mouse, keyboard | J15: AiO Lenovo M810Z | K15: 140000174/Z000054 | L15: Инвентарник наклеен | N15: 1-09 второй этаж HSE | O15: S4FM3374 | P15: ="RUTL-" & RIGHT(O15,8) -> RUTL-S4FM3374 | V15: ULTRAVNC | Y15: Акт 07.03.2023
A16: 13 | B16: - | C16: склад MU движки | D16: need check | E16: Rus | F16: локальная учетка как у mu asse | H16: M&U, PLE | I16: Workstation, Monitor(Lenovo 19" LT 1952p Black/240000010-0002)mouse, keyboard | J16: Lenovo ThinkCenter M73((24000010)) | K16: 00000000214 | L16: инвентарник MOC наклеен | N16: СКЛАД | O16: PC017THP | P16: ="RUTL-" & RIGHT(O16,8) -> RUTL-PC017THP | Q16: Внесены в Passwork | R16: Libre office | T16: Windows 10 Pro - 22H2/19045 | U16: VK7JG-NPHTM-C97JM-9MPGT-3V66T | V16: ULTRAVNC / MESH | W16: No Administrator rights | X16: Кудрявцев Д. | Y16: Акт 20.03.2025
