Workbook

Sheet ПК с 1 владельцем
B1: Табельный номер / Employee ID | C1: Физлицо / Owner | D1: Статус пк ( была ли модернизация) / Modernisation, repairing history | E1: Тип домена / Domain Type | F1: Имя на английском / English name | G1: Должность / Position (Rus / Eng) | H1: Отдел / Department | I1: Комплектация / Equipment | J1: Тип и модель ПК / PC type and model | K1: Инвентарный номер / Inventory number | L1: Инвентарный номер наклеен? / Is the inventory number affixed? | M1: где хранится информация о компе | N1: Местоположение ПК / Location | O1: Серийный номер / Serial Number | P1: Имя компьютера / PC Domain Name | Q1: Passwork | R1: Тип ПО офис / Office type | S1: Ключ офиса / License key Office | T1: ОС тип / OS Type | U1: Ключ ОС / Key OS | V1: ПО удалённого управления / Remote control | W1: Админ права / Admin permissions | X1: Кто подготовил / Who installed | Y1: Дата выдачи / Issue Date | Z1: Дата покупки / Purchasing Date | AA1: Примечание / Comment
A2: =A1+1 -> 1 | B2: 36 | C2: Живов Сергей Викторович | D2: Модернизация не требуется/normal (no need to upgrade) | E2: Rus | G2: Заместитель генерального директора по производству | H2: MD | I2: Laptop,mouse | J2: Laptop ThinkBook 16 G7 ARP 3 | O2: PW0LW3V5 | P2: ="RUTL-" & RIGHT(O2,8) -> RUTL-PW0LW3V5 | R2: Libre office | T2: Windows 11 Pro | U2: 93TQN-DYGPM-FPQ9C-2X3QP-4RHJ6 | V2: ULTRAVNC / MESH | W2: No Administrator rights | X2: Мелёшкин С. | AA2: С НДС 64660 БЕЗ НДС 53000

Sheet ПК с 2 и более владельцами
A1: № | B1: Табельный номер / Employee ID | C1: Физлицо / Owner | D1: История модернизаций, ремонтов / Modernisation, repairing history | E1: Тип домена / Domain Type | F1: Имя на английском / English name | G1: Должность / Position (Rus / Eng) | H1: Отдел / Department | I1: Комплектация / Equipment | J1: Тип и модель ПК / PC type and model | K1: Инвентарный номер / Inventory number | L1: Инвентарный номер наклеен? / Is the inventory number affixed? | M1: где хранится информация о компе | N1: Местоположение / Location | O1: Серийный номер / Serial Number | P1: Имя компьютера / PC Domain Name | Q1: TeamPass, Passwork? | R1: Тип ПО офис / Office type | S1: Ключ офиса / License key Office | T1: ОС тип / OS Type | U1: Ключ ОС / Key OS | V1: ПО удалённого управления / Remote control | W1: Админ права / Admin permissions | X1: Кто подготовил / Who installed | Y1: Дата выдачи / Issue Date | Z1: Дата покупки / Purchasing Date | AA1: Примечание / Comment
A2: 1 | B2: 6859 7841 13454 | C2: Стадольская Оксана Николаевна Долгов Ярослав Андреевич Клементьев Виталий Владимирович | D2: Модернизация не требуется/normal (no need to upgrade) | E2: Rus | F2: Stadolskaya Oksana Dolgov Yaroslav | G2: начальник участка цеха движков / Мастер 2 категории | H2: ES, ES MD, ES AS | I2: AiO, mouse, keyboard | J2: AiO Lenovo M810Z | K2: 140000062/Z000101 | L2: наклеить | N2: engine shop | O2: PC0MYXTZ | P2: ="RUTL-" & RIGHT(O2,8) -> RUTL-PC0MYXTZ | Q2: Внесены в Passwork | T2: Windows 10 Pro - 22H2/19045 | V2: ULTRAVNC / MESH | W2: No administrator rights | X2: Кудрявцев Д. / Мартынов Д. | Y2: акт 07.11.2023 / 03.09.2025 / 05.12.2025
A3: =1+A2 -> 2 | B3: 6218 10700 | C3: Дуплина Татьяна Александровна Филиппова Татьяна Денисовна | D3: Модернизация не требуется/normal (no need to upgrade) | E3: Rus | F3: Duplina Tatyana Filippova Tatyana | G3: Мастер 2 категории Оператор (промоушен на специалиста TPS) | H3: ES, ES MD, ES AS | I3: AiO, mouse, keyboard | J3: AiO Lenovo M810Z | K3: 140000172/Z000052 | L3: наклеить | N3: engine shop | O3: S4FM3331 | P3: ="RUTL-" & RIGHT(O3,8) -> RUTL-S4FM3331 | Q3: Внесены в Passwork | R3: MS Office | T3: Windows 10 Pro - 22H2/19045 | U3: R38X3-J4NJR-CRXGD-KB992-J44C2 | V3: ULTRAVNC / MESH | W3: No administrator rights | X3: Кудрявцев Д. | Y3: Акт 11.11.2025 / 19.11.2025

Sheet Технические ПК
A1: # | B1: Technical_PC
B2: Табельный номер / Employee ID | C2: Физлицо / Owner | D2: История модернизаций, ремонтов / Modernisation, repairing history | E2: Тип домена / Domain Type | F2: Имя на английском / English name | G2: Должность / Position (Rus / Eng) | H2: Отдел / Department | I2: Комплектация / Equipment | J2: Тип и модель ПК / PC type and model | K2: Инвентарный номер / Inventory number | L2: Инвентарный номер наклеен? / Is the inventory number affixed? | M2: где хранится информация о компе | N2: Местоположение / Location | O2: Серийный номер / Serial Number | P2: Имя компьютера / PC Domain Name | Q2: TeamPass, Passwork? | R2: Тип ПО офис / Office type | S2: Ключ офиса / License key Office | T2: ОС тип / OS Type | U2: Ключ ОС / Key OS | V2: ПО удалённого управления / Remote control | W2: Админ права / Admin permissions | X2: Кто подготовил / Who installed | Y2: Дата выдачи / Issue Date | Z2: Дата покупки / Purchasing Date | AA2: Примечание / Comment
A3: 1 | C3: Весовая Акт Казазаев 19-09-2025 | D3: была модернизация/upgraded (SSD 480 +RAM8) | E3: Rus | H3: GA_для весового контроля | I3: AiO, -мышь свою оставил (личная), keyboard | J3: AiO Lenovo S400Z | K3: 150000006/Z000012 | L3: Наклеить | N3: СКЛАД | O3: P901FSPN | P3: ="RUTL-" & RIGHT(O3,8) -> RUTL-P901FSPN | X3: Летунов А. | Y3: Акт 18,09,2025 | AA3: Норм
A4: 2 | C4: Куан Хэн акт 08-02-2019 | D4: очень старый /old(2015-2017 г) | E4: Rus | H4: GA_для комендантов общежития | I4: Workstation, Monitor(Lenovo 19" LT 1952p Black/240000014-0002)mouse, keyboard | J4: WorkStation Lenovo ThinkCenter M73(24000014) | K4: 00000000315 | L4: Наклеить | N4: local acc Dormitory.105-106 | O4: PC017TGV | P4: ="RUTL-" & RIGHT(O4,8) -> RUTL-PC017TGV

Sheet Склад, ремонт, ожидающие
A1: 0 | G1: На складе
A2: № | B2: Табельный номер / Employee ID | C2: Физлицо / Owner | D2: История модернизаций, ремонтов / Modernisation, repairing history | E2: Тип домена / Domain Type | F2: Имя на английском / English name | G2: Должность / Position (Rus / Eng) | H2: Отдел / Department | I2: Комплектация / Equipment | J2: Тип и модель ПК / PC type and model | K2: Инвентарный номер / Inventory number | L2: Инвентарный номер наклеен? / Is the inventory number affixed? | M2: где хранится информация о компе | N2: Местоположение / Location | O2: Серийный номер / Serial Number | P2: Имя компьютера / PC Domain Name | Q2: TeamPass, Passwork? | R2: Тип ПО офис / Office type | S2: Ключ офиса / License key Office | T2: ОС тип / OS Type | U2: Ключ ОС / Key OS | V2: ПО удалённого управления / Remote control | W2: Админ права / Admin permissions | X2: Кто подготовил / Who installed | Y2: Дата выдачи / Issue Date | Z2: Дата покупки / Purchasing Date | AA2: Примечание / Comment
A3: 1 | C3: по тендеру RDD новые без офиса | D3: Модернизация не требуется/normal (no need to upgrade) | E3: Rus | I3: Laptop | J3: Laptop MSI Modern 15 F1MG-800XRU | K3: поставить на учет | L3: Наклеить | N3: СКЛАД BSS | O3: C2507N0002756 | P3: ="RUTL-" & RIGHT(O3,8) -> RUTL-N0002756 | W3: No Administrator rights | X3: Летунов А. | Z3: 45987 | AA3: Стоимость ПК без НДС 59 160руб
A4: =#REF!+1 -> #REF! | B4: документы на списание подписаны | C4: отдали на утилизацию 24-12-2025 | E4: 💩 | G4: начали подготовку к утилизации | H4: утилизация 2025 | I4: Laptop | J4: laptop HP ProBook455(240000002) | K4: 00000000468 | L4: инвентарник MOC наклеен | M4: CND4434S1J | N4: разобраны/готовы к передаче ga
A5: =A4+1 -> #REF! | B5: документы на списание подписаны | C5: отдали на утилизацию 24-12-2025 | E5: 💩 | G5: начали подготовку к утилизации | H5: утилизация 2025 | I5: Laptop | J5: Laptop Lenovo V 130 | K5: 00000019366(13) | L5: инвентарник MOC наклеен | M5: R90T9488 | N5: разобраны/готовы к передаче ga
A6: =A5+1 -> #REF! | B6: документы на списание подписаны | C6: отдали на утилизацию 24-12-2025 | E6: 💩 | G6: начали подготовку к утилизации | H6: утилизация 2025 | I6: Laptop | J6: Laptop Lenovo V 130 | K6: 00000019366(1) | L6: инвентарник MOC наклеен | M6: R90SRSH8 | N6: разобраны/готовы к передаче ga
A7: =A6+1 -> #REF! | B7: документы на списание подписаны | C7: отдали на утилизацию 24-12-2025 | E7: 💩 | G7: начали подготовку к утилизации | H7: утилизация 2025 | I7: Laptop, mouse,bag | J7: Laptop Lenovo V 130 | K7: 00000019366(8) | L7: инвентарник MOC наклеен | M7: R90T9481 | N7: разобраны/готовы к передаче ga
A8: =A7+1 -> #REF! | B8: документы на списание подписаны | C8: отдали на утилизацию 24-12-2025 | E8: 💩 | G8: начали подготовку к утилизации | H8: утилизация 2025 | I8: Laptop | J8: Laptop Lenovo V510 | K8: 00000011577 | L8: инвентарник MOC наклеен | M8: LR08MD6L | N8: разобраны/готовы к передаче ga
A9: =A8+1 -> #REF! | B9: документы на списание подписаны | C9: отдали на утилизацию 24-12-2025 | E9: 💩 | G9: начали подготовку к утилизации | H9: утилизация 2025 | I9: Laptop | J9: Laptop Lenovo V110 | K9: 00000010789 | L9: инвентарник MOC наклеен | M9: R90QFQ01 | N9: разобраны/готовы к передаче ga
A10: =A9+1 -> #REF! | B10: документы на списание подписаны | C10: отдали на утилизацию 24-12-2025 | E10: 💩 | G10: начали подготовку к утилизации | H10: утилизация 2025 | I10: Laptop | J10: Laptop Lenovo V110 | K10: 00000010790 | L10: инвентарник MOC наклеен | M10: R90QFQ0B | N10: разобраны/готовы к передаче ga
A11: =A10+1 -> #REF! | B11: документы на списание подписаны | C11: отдали на утилизацию 24-12-2025 | E11: 💩 | G11: начали подготовку к утилизации | H11: утилизация 2025 | I11: WorkStation.monitor Philips,mouse,keyboard | J11: WorkStation Acer Aspire TC-605+monitor Philips(240000006) | K11: 00000000010 | L11: инвентарник MOC наклеен | M11: DTSRQER08542400B653000 | N11: разобраны/готовы к передаче ga
A12: =A11+1 -> #REF! | B12: документы на списание подписаны | C12: отдали на утилизацию 24-12-2025 | E12: 💩 | G12: начали подготовку к утилизации | H12: утилизация 2025 | I12: Desktop,monitor | J12: Lenovo ThinkCentre M73z | K12: 00000020993 | L12: инвентарник MOC наклеен | M12: PC017TCJ | N12: разобраны/готовы к передаче ga
A13: =A12+1 -> #REF! | B13: документы на списание подписаны | C13: отдали на утилизацию 24-12-2025 | E13: 💩 | G13: начали подготовку к утилизации | H13: утилизация 2025 | I13: Desktop, Monitor(Lenovo 19" LT 1952p Black/240000011-0002)mouse, keyboard | J13: Lenovo ThinkCenter M73/240000011 | K13: 00000000332 | L13: инвентарник MOC наклеен | M13: PC017TH4 | N13: разобраны/готовы к передаче ga
A14: =A13+1 -> #REF! | B14: документы на списание подписаны | C14: отдали на утилизацию 24-12-2025 | E14: 💩 | G14: начали подготовку к утилизации | H14: утилизация 2025 | I14: WorkStation,monitor,mouse,keyboard | J14: Lenovo ThinkCentre M73 | K14: 00000000314 | L14: инвентарник MOC наклеен | M14: PC017TCT | N14: разобраны/готовы к передаче ga
A15: =A14+1 -> #REF! | B15: документы на списание подписаны | C15: отдали на утилизацию 24-12-2025 | E15: 💩 | G15: начали подготовку к утилизации | H15: утилизация 2025 | I15: Workstation, Monitor(Lenovo 19" LT 1952p Black/240000012-0002)mouse, keyboard | J15: Lenovo ThinkCenter M73((24000012)) | K15: 000000333 | L15: инвентарник MOC наклеен | M15: PC017TGK | N15: разобраны/готовы к передаче ga
A16: =A15+1 -> #REF! | B16: документы на списание подписаны | C16: отдали на утилизацию 24-12-2025 | E16: 💩 | G16: начали подготовку к утилизации | H16: утилизация 2025 | I16: Laptop | J16: Laptop Lenovo V510 | K16: 00000011590 | L16: инвентарник MOC наклеен | M16: LR08MD3C | N16: разобраны/готовы к передаче ga
... A20: =A19+1 -> #REF! | B20: Заключение О нецелесообразности дальнейшего использования ИТ активов № RDC-BSS-10-2025-007От 30-10-2025 г. | C20: отдали на утилизацию 12-12-2025 | E20: 💩 | G20: документы на списание переданы на проверку FD 08-12-2025/ начали подготовку к утилизации | H20: утилизация 2025 | I20: Laptop | J20: Laptop LenovoX270 | K20: 140000069/Z000095 | L20: Наклеить | M20: PC0NBSGN | N20: разобраны/готовы к передаче ga
A21: =A20+1 -> #REF! | B21: "Заключение О нецелесообразности дальнейшего использования ИТ активов № RDC-BSS-10-2025-003 От 30-10-2025 г. | C21: отдали на утилизацию 12-12-2025 | E21: 💩 | G21: документы на списание переданы на проверку FD 08-12-2025/ начали подготовку к утилизации | H21: утилизация 2025 | I21: Laptop | J21: Laptop Lenovo ThinkPad EDGE E570 | K21: 150000028/Z000006 | L21: Наклеить | M21: PF0NFU3K | N21: разобраны/готовы к передаче ga | O21: BC7J4-MN7BC-MY7J2-RT6FY-MY49C
A22: =A21+1 -> #REF! | B22: "Заключение О нецелесообразности дальнейшего использования ИТ активов № RDC-BSS-10-2025-002 От 30-10-2025 г. | C22: отдали на утилизацию 12-12-2025 | D22: акумулятор офф | E22: 💩 | G22: документы на списание переданы на проверку FD 08-12-2025/ начали подготовку к утилизации | H22: утилизация 2025 | I22: Laptop | J22: Laptop Lenovo ThinkPad EDGE E570 | K22: 140000054/Z000108 | L22: Наклеить | M22: PF0W1977 | N22: разобраны/готовы к передаче ga
A23: =A22+1 -> #REF! | B23: Заключение О нецелесообразности дальнейшего использования ИТ активов № RDC-BSS-10-2025-006От 30-10-2025 г. | C23: отдали на утилизацию 12-12-2025 | E23: 💩 | G23: документы на списание переданы на проверку FD 08-12-2025/ начали подготовку к утилизации | H23: утилизация 2025 | I23: Laptop | J23: Laptop Lenovo ThinkPad EDGE E560 | K23: 140000042/Z000126 | L23: Наклеить | M23: PF0LC4HW | N23: разобраны/готовы к передаче ga | O23: Installed Key:237XB-GDJ7B-MV8MH-98QJM-24367(Windows 7 Professional)
A24: =A23+1 -> #REF! | B24: акумулятор + клавиатура офф Заключение О нецелесообразности дальнейшего использования ИТ активов № RDC-BSS-10-2025-005 От 30-10-2025 г. | C24: отдали на утилизацию 20-12-2025 | E24: 💩 | G24: документы на списание переданы на проверку FD 08-12-2025/ начали подготовку к утилизации | H24: утилизация 2025 | I24: Laptop | J24: Laptop Lenovo ThinkPad EDGE E560 | K24: 140000024/Z000055 | L24: Наклеить | M24: PF-0IP638 | N24: разобраны/готовы к передаче ga | O24: 77F4C-NCDHK-TWXFK-RMBHV-8HV82
A25: =A24+1 -> #REF! | B25: Заключение О нецелесообразности дальнейшего использования ИТ активов № RDC-BSS-10-2025-004 От 30-10-2025 г. | C25: отдали на утилизацию 12-12-2025 | E25: 💩 | G25: документы на списание переданы на проверку FD 08-12-2025/ начали подготовку к утилизации | H25: утилизация 2025 | I25: Laptop | J25: Laptop Lenovo ThinkPad EDGE E560 | K25: 140000039/Z000128 | L25: Наклеить | M25: PF0L9ESP | N25: разобраны/готовы к передаче ga
A26: =A25+1 -> #REF! | C26: отдали на утилизацию 09-12-2025 | E26: 💩 | G26: документы на списание подписаны(кит.форма) Лежит в коробке на утиль ( отдали на утилизацию 09-12-2025) | H26: утилизация 2025 | I26: Laptop | J26: Laptop LenovoT440p | K26: не на балансе | L26: MOSCOW(HMR) | M26: PC01389D | N26: разобраны/готовы к передаче ga
A27: =A26+1 -> #REF! | C27: отдали на утилизацию 09-12-2025 | E27: 💩 | G27: документы на списание подписаны(кит.форма) Лежит в коробке на утиль ( отдали на утилизацию 09-12-2025) | H27: утилизация 2025 | I27: Desktop,monitor | J27: Desktop ThinkCentre Lenovo M92p | K27: не на балансе | L27: MOSCOW(HMR) | M27: PB02NZP2 | N27: разобраны/готовы к передаче ga
A28: =A27+1 -> #REF! | C28: отдали на утилизацию 09-12-2025 | E28: 💩 | G28: документы на списание подписаны(кит.форма) Лежит в коробке на утиль ( отдали на утилизацию 09-12-2025) | H28: утилизация 2025 | I28: Desktop,monitor | J28: Desktop ThinkCentre Lenovo M92p | K28: не на балансе | L28: MOSCOW(HMR) | M28: PBP3W3V | N28: разобраны/готовы к передаче ga
A29: =A28+1 -> #REF! | C29: отдали на утилизацию 09-12-2025 | E29: 💩 | G29: документы на списание подписаны(кит.форма) Лежит в коробке на утиль ( отдали на утилизацию 09-12-2025) | H29: утилизация 2025 | I29: Desktop,monitor | J29: M 73 Desktop | K29: не на балансе | L29: MOSCOW(HMR) | M29: PB02UAKC | N29: разобраны/готовы к передаче ga
A30: =A29+1 -> #REF! | C30: отдали на утилизацию 09-12-2025 | E30: 💩 | G30: документы на списание подписаны(кит.форма) Лежит в коробке на утиль ( отдали на утилизацию 09-12-2025) | H30: утилизация 2025 | I30: Desktop,monitor | J30: M 93p Desktop | K30: не на балансе | L30: MOSCOW(HMR) | M30: S4G32593 | N30: разобраны/готовы к передаче ga
A31: =A30+1 -> #REF! | C31: отдали на утилизацию 09-12-2025 | E31: 💩 | G31: документы на списание подписаны(кит.форма) Лежит в коробке на утиль ( отдали на утилизацию 09-12-2025) | H31: утилизация 2025 | I31: Desktop,monitor | J31: Desktop ThinkCentre Lenovo M92p | K31: не на балансе | L31: MOSCOW(HMR) | M31: PBP3W3Y | N31: разобраны/готовы к передаче ga
A32: =A31+1 -> #REF! | C32: отдали на утилизацию 09-12-2025 | E32: 💩 | G32: документы на списание подписаны(кит.форма) Лежит в коробке на утиль ( отдали на утилизацию 09-12-2025) | H32: утилизация 2025 | I32: Desktop,monitor | J32: Lenovo ThinkCenter M73 | K32: не на балансе | L32: MOSCOW(HMR) | M32: S4G02565 | N32: разобраны/готовы к передаче ga
A33: =A32+1 -> #REF! | C33: отдали на утилизацию 09-12-2025 | E33: 💩 | G33: документы на списание подписаны(кит.форма) Лежит в коробке на утиль ( отдали на утилизацию 09-12-2025) | H33: утилизация 2025 | I33: Desktop,monitor | J33: Lenovo ThinkCenter M73p | K33: не на балансе | L33: MOSCOW(HMR) | M33: PC017TD7 | N33: разобраны/готовы к передаче ga
A34: =A33+1 -> #REF! | C34: отдали на утилизацию 09-12-2025 | E34: 💩 | G34: утилизирован /остатки корпуса и механизмов переданы на утилизацию вместе с пк хмр 09-12-2025 | H34: утилизация 2025 | I34: Laptop | J34: DELL Latitude 5480(от комплекта феникса) | K34: не на балансе | L34: У MU с этикет принтером, вырбаны usb, залита клавиатура, отходит экранразобрали как донора , на балансе не стоял | M34: 1B7RFH2 | N34: разобрали на части в качетве донора от него есть только части корпуса и сломанная напополам материнка
H35: списание 2019 | I35: laptop | J35: Ноутбук Lenovo ThinkPad EDGE E560 (20EVS00400) | K35: 150000008 | L35: PFOLC44N | M35: RUTL-PFOLC44N | N35: стройка(утерян)
H36: списание 2019 | I36: laptop | J36: laptop Lenovo L580 | K36: 14000145 | L36: - | M36: - | N36: -
H37: списание 2018 | I37: laptop | J37: Lenovo THINKPAD L450 (s/n PF-07688U) | K37: 140000007 | L37: Lenovo THINKPAD L450 (s/n PF-07688U) | M37: PF-07688U | N37: утерян ПОГОРЕЛОВ
H38: списание 2018 | I38: laptop | J38: Ноутбук 15.6" Lenovo V310-15ISK (80SY000WRK) | K38: 140000030 | L38: RUTL-LR062AQD | N38: у игоря(на списание)
H39: Списание 2022 | I39: laptop | J39: laptop Lenovo L580 | K39: 14000151 | L39: 12TW3R | M39: RUTL-12TW3R | N39: инженерный ноут (у оладина)
H40: списание 2023 | I40: laptop | J40: Lenovo THINKPAD L450 | K40: 140000009 | L40: PF09H1BT | M40: PF09H1BT | N40: Pogorelov Dmitriy
H41: (need to dismiss) | I41: Laptop, mouse,bag | J41: Laptop Lenovo V110 | K41: 00000011066 | L41: инвентарник MOC наклеен | M41: 1-03 окраска 1эт | N41: R90QN4W0 | Q41: Ланкин
H42: была замена по браку | I42: AiO, mouse, keyboard | J42: AIO Dell Inspiron 5400 | K42: новая партия | L42: BM4HDF2 | M42: RUTL-BM4HDF2 | N42: замена по браку | Q42: произведена замена
M43: ДРУГОЕ/other
...

Sheet ОПГ РНДМоушен
A1: № | B1: Табельный номер / Employee ID | C1: Физлицо / Owner | D1: История модернизаций, ремонтов / Modernisation, repairing history | E1: Тип домена / Domain Type | F1: Имя на английском / English name | G1: Должность / Position (Rus / Eng) | H1: Отдел / Department | I1: Комплектация / Equipment | J1: Тип и модель ПК / PC type and model | K1: Инвентарный номер / Inventory number | L1: Инвентарный номер наклеен? / Is the inventory number affixed? | M1: где хранится информация о компе | N1: Местоположение / Location | O1: Серийный номер / Serial Number | P1: Имя компьютера / PC Domain Name | Q1: TeamPass, Passwork? | R1: Тип ПО офис / Office type | S1: Ключ офиса / License key Office | T1: ОС тип / OS Type | U1: Ключ ОС / Key OS | V1: ПО удалённого управления / Remote control | W1: Админ права / Admin permissions | X1: Кто подготовил / Who installed | Y1: Дата выдачи / Issue Date | Z1: Дата покупки / Purchasing Date | AA1: Примечание / Comment
A2: =#REF!+1 -> #REF! | B2: 12152 | C2: Башин Артем Геннадьевич | D2: обратно не принимать, пк подвергся вандализму | E2: Rus | F2: Bashin Artem | G2: Инженер по технологии силовых агрегатов 2 категории | H2: R&D, PTD, CTS | I2: Laptop, mouse | J2: Laptop IRBIS 15NBP3507 | K2: поставить на учет | L2: наклеить | N2: 1-07 четвертый этаж | O2: F2715NBP35070821711 | P2: ="RUTL-" & RIGHT(O2,8) -> RUTL-70821711 | Q2: Внесены в Passwork | R2: Libre office | T2: Windows 10 Pro - 22H2/19045 | U2: 3666N-9MDY9-6GH86-PMR8H-MBH22 | V2: ULTRAVNC / MESH | W2: No Administrator rights | X2: Кудрявцев Д. | Y2: Акт 21.05.2025
A3: =#REF!+1 -> #REF! | B3: 9261 | C3: Герасина Анастасия Сергеевна | D3: Модернизация не требуется/normal (no need to upgrade) | E3: Rus | F3: Gerasina Anastasia | G3: Специалист по управлению проектами | H3: R&D, PRJMD, PMS I | I3: Laptop, mouse,bag | J3: Laptop Lenovo L340 | K3: 10000001789 | L3: инвентарник ОС наклеен | N3: 1-07 четвертый этаж | O3: PF24ABRT | P3: ="RUTL-" & RIGHT(O3,8) -> RUTL-PF24ABRT | Q3: Внесены в Passwork | R3: MS Office | U3: DGC9N-BJ7FW-WJTWW-DR8DC-JB49G | V3: ULTRAVNC / MESH | X3: Летунов А. | Y3: Акт 27.08.2024
A4: =#REF!+1 -> #REF! | B4: 1540 | C4: Никитин Александр Валерьевич | D4: Модернизация не требуется/normal (no need to upgrade) | E4: Rus | F4: Nikitin Aleksandr | G4: Специалист 3 категории | H4: R&D, PRJMD, PMS I | I4: Laptop,mouse+Lan-USB | J4: Laptop Lenovo V15 G1+Lan-USB | K4: 100000001627 | L4: Наклеить | M4: Внесен в ITSM AST0000878 | N4: 1-07 четвертый этаж | O4: PF2TXSE1 | P4: ="RUTL-" & RIGHT(O4,8) -> RUTL-PF2TXSE1 | R4: 2016 for home and business (BOX) | V4: ULTRAVNC | W4: Admin | Y4: Акт 30.09.2021
A5: 9 | C5: Используется для микроскопа | D5: НОВЫЙ/New(no need to upgrade) | G5: на перепродажу? | H5: R&D, lab | I5: WorkStation,monitor(не наш),mouse,keyboard | J5: Workstation Регард К00826/1(РДЦБ-000826) | K5: 10000003812 | L5: Наклеить | N5: 1-07 4 этаж, лаборатория | O5: 07E0210_O31B057075 | P5: ="RUTL-" & RIGHT(O5,8) -> RUTL-1B057075 | U5: VYN9P-JQVWF-T3P78-TG4KT-P7JXC
A6: =#REF!+1 -> #REF! | C6: Выдан с технической учетной записью на 4 пользователей (TechniciansVTS)(корнеев акт 06-06-2024) | D6: требуется модернизация/ need to modernisation | G6: что будем делать? | H6: R&D, VTS | I6: Laptop, mouse | J6: Laptop Lenovo V510 | K6: 00000011575 | L6: инвентарник MOC наклеен | N6: 1-07 четвертый этаж | O6: LR08MD5Z | P6: ="RUTL-" & RIGHT(O6,8) -> RUTL-LR08MD5Z | Y6: Акт 06-06-24 | Z6: 43397
A7: =A6+1 -> #REF! | C7: Технический(брилев акт 21-02-2024) | D7: требуется модернизация/ need to modernisation | G7: что будем делать? | H7: R&D, RUS QMD | I7: Laptop, mouse,bag | J7: laptop Lenovo E560 | K7: 140000023/Z000135 | L7: Наклеить | N7: 1-07 четвертый этаж | O7: PF0IP8V3 | P7: ="RUTL-" & RIGHT(O7,8) -> RUTL-PF0IP8V3

Sheet ДонМотор(КАЛУГА)
H1: Компьютер | P1: где хранится Учетная запись пользователя | Q1: Office software | R1: License key Office | S1: Operating system | U1: Other installed software | W1: Акт о выдаче
A2: # | B2: Код(Employee ID) | C2: Физлицо/name | D2: тип домена | E2: English name | F2: Должность / Position (Rus / Eng) | G2: Отдел/departament | H2: type of pc | I2: Компьютер(модель)/model | J2: инвентарный номер/inventory number | K2: инвентарник наклеен/да/нет | L2: где хранится информация о компе | M2: местоположение/workplace | N2: Серийный номер/serial.number | O2: Имя компьютера/ Name of PC's | P2: примечание/Notice | S2: Type | T2: Key(OS code) | U2: remote control | V2: ADMIN permissions | W2: Кто подготовил/накосячил/ | X2: Дата выдачи
A3: JMR-001 | B3: S.Kuznetsova.JMR | C3: Кузнецова Светлана | D3: Rus | E3: Kuznetsova Svetlana | F3: Бухгалтер ЖМР | G3: FD (RUIXIN) | H3: Laptop, mouse,bag | I3: Laptop IRBIS 17NBP4502 | J3: 100000003573 | K3: - | L3: продано по договору от 23-10-2025 | M3: TULA Plant | N3: F2717NBP4502103153 | O3: ="RUKLG-" & RIGHT(N3, 8) -> RUKLG-02103153 | T3: VK7JG-NPHTM-C97JM-9MPGT-3V66T | U3: ULTRAVNC \ MESH | W3: Летунов А. | X3: Акт от 13.12.2024
A4: JMR-002 | B4: 11861 | C4: Тё Константин Валерьевич | D4: Rus | E4: Tyo Konstantin | F4: Руководитель Группы заказов | G4: ORD (RUIXIN) | H4: Laptop, mouse,bag | I4: Lenovo IdeaPad Slim 3 16IAH8 | J4: НЕ НА БАЛАНСЕ/Belong to Ruixin | K4: - | L4: Belong to Ruixin | M4: KALUGA Plant | N4: PF4TN6C9 | O4: ="RUKLG-" & RIGHT(N4, 8) -> RUKLG-PF4TN6C9 | P4: Внесены в Passwork | Q4: office (был активирован с Москвы) | S4: Windows 10 Pro - 22H2/19045 x64 | T4: VK7JG-NPHTM-C97JM-9MPGT-3V66T | U4: ULTRAVNC \ MESH | V4: No administrator rights | W4: Летунов А. | X4: Акт от 24.02,2025
A5: JMR-003 | B5: 11862 | C5: Онуфриева Людмила Сергеевна | D5: Rus | E5: Onufrieva Liudmila | F5: Ведущий специалист Группы заказов | G5: ORD (RUIXIN) | H5: Laptop, mouse,bag | I5: Lenovo IdeaPad Slim 3 16IAH8 | J5: НЕ НА БАЛАНСЕ/Belong to Ruixin | K5: - | L5: Belong to Ruixin | M5: KALUGA Plant | N5: PF4TN9TH | O5: ="RUKLG-" & RIGHT(N5, 8) -> RUKLG-PF4TN9TH | P5: Внесены в Passwork | Q5: office kms (был активирован с Москвы) | S5: Windows 10 Pro - 22H2/19045 x64 | T5: VK7JG-NPHTM-C97JM-9MPGT-3V66T странно что ключ уже использовался на пк PF4TN6C9... | U5: ULTRAVNC \ MESH | V5: No administrator rights | W5: Кудрявцев Д. | X5: Акт от 03.03.2025
A6: JMR-004 | B6: .JMR | C6: Кочубеев Николай Валерьевич/Малютин Павел Сергеевич | D6: Rus | E6: Kochubeev Nikolay / Malyutin Pavel | F6: Аудитор проверки качества | G6: QIS (RUIXIN) | H6: Laptop, mouse,bag | I6: Lenovo IdeaPad Slim 3 16IAH8 | J6: НЕ НА БАЛАНСЕ/Belong to Ruixin | K6: - | L6: Belong to Ruixin | M6: KALUGA Plant | N6: PF4VBETB | O6: ="RUKLG-" & RIGHT(N6, 8) -> RUKLG-PF4VBETB | P6: Внесены в Passwork | Q6: office kms (был активирован с Москвы) | S6: Windows 10 Pro - 22H2/19045 x64 | T6: W269N-WFGWX-YVC9B-4J6C9-T83GX | U6: ULTRAVNC \ MESH | V6: No administrator rights | W6: Кудрявцев Д. | X6: Акт от 28.03.2025
A7: JMR-005 | B7: gw04000038 | C7: Сысоев Тимур Анатольевич | D7: Rus | E7: Timur Sysoev | F7: ведущий специалист по таможенному оформлению | G7: ILD,CO (RUIXIN) | H7: Laptop, mouse, переходник | I7: Lenovo IdeaPad Slim 3 16IAH8 | J7: НЕ НА БАЛАНСЕ/Belong to Ruixin | K7: - | L7: Belong to Ruixin | M7: KALUGA Plant | N7: PF4TN9VG | O7: ="RUKLG-" & RIGHT(N7, 8) -> RUKLG-PF4TN9VG | P7: Внесены в Passwork | Q7: office kms (был активирован с Москвы) | S7: Windows 10 Pro - 22H2/19045 x64 | T7: W269N-WFGWX-YVC9B-4J6C9-T83GX | U7: ULTRAVNC \ MESH | V7: No administrator rights | W7: Климанов А | X7: Акт от 20.03.2026
A8: JMR-006 | B8: .JMR | C8: Максимова Анастасия Юрьевна | D8: Rus | E8: Maximova Anastasia | F8: ведущий координатор по транспорту | G8: ILD,CO (RUIXIN) | H8: Laptop, mouse, переходник | I8: Lenovo IdeaPad Slim 3 16IAH8 | J8: НЕ НА БАЛАНСЕ/Belong to Ruixin | K8: - | L8: Belong to Ruixin | M8: KALUGA Plant | N8: PF4TNPWE | O8: ="RUKLG-" & RIGHT(N8, 8) -> RUKLG-PF4TNPWE | P8: Внесены в Passwork | Q8: office kms (был активирован с Москвы) | S8: Windows 10 Pro - 22H2/19045 x64 | U8: ULTRAVNC \ MESH | V8: No administrator rights | W8: Климанов А. | X8: Акт от 24.04.2025
A9: JMR-007 | B9: .JMR | C9: Дронов Дмитрий Владимирович | D9: Rus | E9: Dronov Dmitry | F9: Руководитель Группы качества | G9: QT (RUIXIN) | H9: Laptop, mouse,bag, Переходник | I9: Lenovo IdeaPad Slim 3 16IAH8 | J9: НЕ НА БАЛАНСЕ/Belong to Ruixin | K9: - | L9: Belong to Ruixin | M9: KALUGA Plant | N9: PF4TNKVQ | O9: ="RUKLG-" & RIGHT(N9, 8) -> RUKLG-PF4TNKVQ | P9: Внесены в Passwork | Q9: office kms (был активирован с Москвы) | S9: Windows 10 Pro - 22H2/19045 x64 | U9: ULTRAVNC \ MESH | V9: No administrator rights | W9: Климанов А. | X9: Акт от 17.04.2025
A10: JMR-008 | B10: .JMR | C10: Кутепова Светлана Леонидовна | D10: Rus | E10: Svetlana Kutepova | F10: HR менеджер | G10: HR (RUIXIN) | H10: Laptop, mouse,bag, Переходник | I10: Lenovo IdeaPad Slim 3 16IAH8 | J10: НЕ НА БАЛАНСЕ/Belong to Ruixin | K10: - | L10: Belong to Ruixin | M10: KALUGA Plant | N10: PF4VCF8K | O10: ="RUKLG-" & RIGHT(N10, 8) -> RUKLG-PF4VCF8K | Q10: office kms (был активирован с Москвы) | S10: Windows 10 Pro - 22H2/19045 x64 | U10: ULTRAVNC \ MESH | V10: No administrator rights | W10: Мартынов Д. | X10: Акт от 18.04.2025
A11: JMR-009 | B11: 1 | C11: Чуракова Екатерина Сергеевна | D11: Rus | E11: Churakova Ekaterina | F11: Инжнер по контролю качеству | G11: QT (RUIXIN) | H11: Laptop, mouse, переходник | I11: Lenovo IdeaPad Slim 3 16IAH8 | J11: НЕ НА БАЛАНСЕ/Belong to Ruixin | K11: - | L11: Belong to Ruixin | M11: KALUGA Plant | N11: PF4TM2AV | O11: ="RUKLG-" & RIGHT(N11, 8) -> RUKLG-PF4TM2AV | P11: Внесены в Passwork | Q11: office kms | S11: Windows 10 Pro - 22H2/19045 x64 | U11: ULTRAVNC \ MESH | V11: No administrator rights | W11: Климанов А | X11: Акт от 10.06.2025
A12: JMR-010 | B12: .JMR | C12: Силанова Ирина Александровна | D12: Rus | E12: Silanova Irina | F12: Координатор по транспорту | G12: ILD,CO (RUIXIN) | H12: Laptop, mouse, переходник | I12: Lenovo IdeaPad Slim 3 16IAH8 | J12: НЕ НА БАЛАНСЕ/Belong to Ruixin | K12: - | L12: Belong to Ruixin | M12: KALUGA Plant | N12: PF4TM2B7 | O12: ="RUKLG-" & RIGHT(N12, 8) -> RUKLG-PF4TM2B7 | P12: Внесены в Passwork | Q12: office kms | S12: Windows 10 Pro - 22H2/19045 x64 | U12: ULTRAVNC \ MESH | V12: No administrator rights | W12: Климанов А | X12: Акт от 21.07.2025
A13: JMR-011 | B13: 12 | C13: Комарова Елена Васильевна | D13: Rus | E13: Komarova Elena | F13: Ведущий Бухгалтер 2 кат. | G13: FD (RUIXIN) | H13: Laptop, mouse,bag | I13: Laptop Acer Aspire 3 | J13: НЕ НА БАЛАНСЕ/Belong to Ruixin | K13: - | L13: Belong to Ruixin | M13: TULA Plant | N13: NXK9YER005426019A73400 | O13: ="RUKLG-" & RIGHT(N13, 8) -> RUKLG-19A73400 | P13: Внесены в Passwork | Q13: Only office / libre office | S13: Windows 11 Pro | T13: 8BBGN-YQMVQ-GK38P-XGCMH-PWF9C | U13: ULTRAVNC \ MESH | V13: No administrator rights | W13: Летунов А. | X13: Акт от 15.09.2025
A14: JMR-012 | B14: 13 | C14: Королёва Юлия Валерьевна | D14: Rus | E14: Koroleva Yuliya | F14: Бухгалтер 2 категории | G14: FD (RUIXIN) | H14: Laptop, mouse,bag | I14: Laptop Acer Aspire 3 | J14: НЕ НА БАЛАНСЕ/Belong to Ruixin | K14: - | L14: Belong to Ruixin | M14: TULA Plant | N14: NXK9YER005426019163400 | O14: ="RUKLG-" & RIGHT(N14, 8) -> RUKLG-19163400 | Q14: Only office / libre office | S14: Windows 11 Pro | T14: XJNHV-3BJ4K-GRPM7-JGFCJ-YP2KC | U14: ULTRAVNC \ MESH | V14: No administrator rights | W14: Летунов А. | X14: Акт от 25,09,2025
A15: JMR-013 | B15: 14 | C15: Севостьянова Татьяна Юрьевна | D15: Rus | E15: Sevostyanova Tatyana | F15: Бухгалтер 2 категории | G15: FD (RUIXIN) | H15: Laptop, | I15: Laptop Acer Aspire 3 | J15: НЕ НА БАЛАНСЕ/Belong to Ruixin | K15: - | L15: Belong to Ruixin | M15: TULA Plant | N15: NXK9YER0054260169E3400 | O15: ="RUKLG-" & RIGHT(N15, 8) -> RUKLG-169E3400 | P15: Внесены в Passwork | Q15: Only office / libre office | S15: Windows 11 Pro | T15: 8FXB7-MN2V7-H4CK8-FQYQG-FVV22 | U15: ULTRAVNC \ MESH | V15: No administrator rights | W15: Летунов А. | X15: Акт от 07.10.2025
A16: JMR-014 | B16: .JMR | C16: Зайцева Елена Анатольевна | D16: Rus | E16: Zaytseva Elena | F16: Бухгалтер 1 категории | G16: FD (RUIXIN) | H16: Laptop,mouse, | I16: Laptop Acer Aspire 3 | J16: НЕ НА БАЛАНСЕ/Belong to Ruixin | K16: - | L16: Belong to Ruixin | M16: TULA Plant (1-07 3) | N16: NXK9YER005426012433400 | O16: ="RUKLG-" & RIGHT(N16, 8) -> RUKLG-12433400 | P16: Внесены в Passwork | Q16: Only office / libre office | S16: Windows 11 Pro | T16: WP7NT-M84RW-K2394-6K4JX-RM49C | U16: ULTRAVNC \ MESH | V16: No administrator rights | W16: Летунов А. | X16: АКТ от 09.12.2025
A17: JMR-015 | B17: 59 | C17: Зайцева Елена Николаевна | D17: Rus | E17: Zaitseva Elena | F17: Бухгалтер 1 кат. | G17: FD (RUIXIN) | H17: Laptop,mouse, bag | I17: Laptop Acer Aspire 3 | J17: НЕ НА БАЛАНСЕ/Belong to Ruixin | K17: - | L17: Belong to Ruixin | M17: TULA Plant | N17: NXK9YER005426013513400 | O17: ="RUKLG-" & RIGHT(N17, 8) -> RUKLG-13513400 | P17: Внесены в Passwork | Q17: Only office / libre office | S17: Windows 11 Pro | T17: XX3MD-FN4HJ-GXYPT-4KXMY-WHV22 | U17: ULTRAVNC \ MESH | V17: No administrator rights | W17: Летунов А. | X17: АКТ от 08.11.2025
A18: JMR-016 | B18: .JMR-13303 | C18: Хорчева Светлана Александровна | D18: Rus | E18: Khorcheva Svetlana | F18: Специалист по группы заказов | G18: ORD (RUIXIN) | H18: Laptop,mouse, bag | I18: Acer Aspire Lite AL15-41 | J18: НЕ НА БАЛАНСЕ/Belong to Ruixin | K18: - | L18: Belong to Ruixin | M18: TULA Plant | N18: UN31ZSI04F533024B50700 | O18: ="RUKLG-" & RIGHT(N18, 8) -> RUKLG-24B50700 | P18: Внесены в Passwork | Q18: Only office / libre office | S18: Windows 11 Pro | T18: VXGCN-Y9XJM-YQW3B-W2K28-W44TG | U18: ULTRAVNC \ MESH | V18: No administrator rights | W18: Летунов А. | X18: Акт 02.12.2025
A19: JMR-017 | B19: A.Gorbanchuk.JMR | C19: Горбанчук Артем Григорьевич (принял Елисеев А.А.) | D19: Rus | E19: Gorbanchuk Artem | F19: Специалист по качеству | G19: QT (RUIXIN) | H19: Laptop, mouse, bag, USB - LAN | I19: Lenovo IdeaPad Slim 3 16IAH8 | J19: НЕ НА БАЛАНСЕ/Belong to Ruixin | K19: - | L19: Belong to Ruixin | M19: KALUGA Plant | N19: PF4V6E1X | O19: ="RUKLG-" & RIGHT(N19, 8) -> RUKLG-PF4V6E1X | P19: Внесены в Passwork | Q19: Only office / libre office | S19: Windows 10 Pro - 22H2/19045 x64 | T19: W269N-WFGWX-YVC9B-4J6C9-T83GX | U19: ULTRAVNC \ MESH | V19: No administrator rights | W19: Кудрявцев Д. | X19: Акт от 30.10.2025
A20: JMR-018 | B20: - | C20: нужно переоформить на Пискарёва Артема Александровича. Это специалист по качеству | D20: Rus | E20: непонятно кто использует/не сдан????? не передают обратно | F20: Специалист по качеству | G20: QT (RUIXIN) | H20: Laptop, mouse,bag | I20: ACD 15 S | J20: НЕ НА БАЛАНСЕ/Belong to HMR | K20: - | L20: Belong to HMR | M20: KALUGA Plant | N20: AH15SI2209110724 | O20: ="RUKLG-" & RIGHT(N20, 8) -> RUKLG-09110724 | Q20: office kms | U20: ULTRAVNC \ MESH | V20: No administrator rights | W20: Климанов А | X20: Акт от 06.02.2025
A21: JMR-019 | B21: .JMR | C21: Крюкова Марина Владимировна | D21: Rus | E21: Kryukova Marina | F21: Специалист по качеству | G21: QT (RUIXIN) | H21: Laptop,mouse, bag | I21: Acer Aspire Lite AL15-41 | J21: НЕ НА БАЛАНСЕ/Belong to Ruixin | K21: - | L21: Belong to Ruixin | M21: TULA Plant | N21: UN31ZSI04F533025070700 | O21: ="RUKLG-" & RIGHT(N21, 8) -> RUKLG-25070700 | Q21: Only office / libre office
A22: JMR-020 | H22: Laptop,mouse, bag | I22: Acer Aspire Lite AL15-41 | J22: НЕ НА БАЛАНСЕ/Belong to Ruixin | K22: - | L22: Belong to Ruixin | M22: TULA Plant | N22: new | O22: ="RUKLG-" & RIGHT(N22, 8) -> RUKLG-new
A23: JMR-021 | H23: Laptop,mouse, bag | I23: Acer Aspire Lite AL15-41 | J23: НЕ НА БАЛАНСЕ/Belong to Ruixin | K23: - | L23: Belong to Ruixin | M23: TULA Plant | N23: new | O23: ="RUKLG-" & RIGHT(N23, 8) -> RUKLG-new
A24: JMR-022 | B24: .JMR | C24: BROCKEN | D24: Rus | E24: не исправен | F24: HAVE A PROBLEM | G24: need return to HMR | H24: Laptop | I24: Laptop IRBIS 15NBC1003 | J24: НЕ НА БАЛАНСЕ/Belong to HMR | K24: - | L24: Belong to HMR | M24: TULA Plant | N24: F2715NBC10030820141 | O24: ="RUKLG-" & RIGHT(N24, 8) -> RUKLG-30820141 | P24: Внесены в Passwork | Q24: office kms (был активирован с Москвы) | S24: Windows 10 Pro - 22H2/19045 x64 | T24: KHFMJ-8NM99-J47WT-TYT7B-7MH22 | U24: ULTRAVNC \ MESH | V24: No administrator rights
A25: JMR-023 | B25: .JMR | C25: BROCKEN | D25: Rus | E25: не исправен | F25: HAVE A PROBLEM | G25: need return to HMR | H25: Laptop, | I25: Laptop IRBIS 15NBC1003 | J25: НЕ НА БАЛАНСЕ/Belong to HMR | K25: - | L25: Belong to HMR | M25: TULA Plant | N25: F2715NBC10030820067 | O25: ="RUKLG-" & RIGHT(N25, 8) -> RUKLG-30820067 | P25: Внесены в Passwork | Q25: office kms (был активирован с Москвы) | S25: Windows 10 Pro - 22H2/19045 x64 | T25: 9HPBR-CN9HG-4G6VP-PDJC2-RVV22 | U25: НЕ ДЕРЖИТ АКУМУЛЯТОР !!! | V25: No administrator rights

Sheet Без компа  другое оборудование
B1: WITHOUT PC
B2: Табельный | C2: ФИО | D2: Статус | F2: Имя и фамилия ENG | G2: Должность | I2: Тип | J2: Модель | K2: Название В домене | N2: S/N:
B3: ? | C3: Стоит на складе, не стоит на балансе | D3: требуется модернизация/ need to modernisation | E3: Rus | F3: Borovikov Alexander | G3: (Студент) технической поддержки | H3: Стоит на складе, не стоит на балансе | I3: Laptop, mouse,bag | J3: Laptop HP Elite Book 840 G3 | K3: НЕУЧТЁНКА ОТ ЯГЕЛОВОЙ | L3: не на балансе | M3: 1-07 2 этаж | N3: 5CG7163V7D | O3: RUTL-5CG1763V7D | P3: Внесены в Passwork | Q3: Libre office | V3: ULTRAVNC \ MESH | W3: no need | X3: Климанов А. | Y3: Акт 04.03.2025
B4: ОТ MU вероятно | C4: Стоит на складе, не стоит на балансе | D4: ? | H4: Стоит на складе, не стоит на балансе | I4: Workstation | J4: Lenovo V530S | K4: Неучтёнка от MU наверное | L4: не на балансе | M4: СКЛАД | N4: YL003MJR | O4: RUTL-YL003MJR
A5: =#REF!+1 -> #REF! | B5: 13375 | C5: Клименок Вероника Сергеевна | D5: Модернизация не требуется/normal (no need to upgrade) | E5: Rus | F5: Klimenok Veronica | G5: Специалист по подбору персонала | H5: HRD, REC, WC REC | I5: Laptop, mouse+Lan-USB | J5: Laptop Lenovo V 130 | K5: 00000019366(14) | L5: инвентарник MOC наклеен | N5: 1-07 Третий этаж | O5: R90T947H | P5: ="RUTL-" & RIGHT(O5,8) -> RUTL-R90T947H | R5: Libre office | T5: Windows 10 Pro - 22H2/19045 | U5: T2NMK-6MYVB-67DTH-8W896-9KXTP | V5: ULTRAVNC / MESH | W5: No Administrator rights | X5: Климанов А. | Y5: Акт 20.11.2025 | Z5: 2019 | AA5: утилизация после замены
C6: Акулиничев Андрей | I6: Display | J6: Xiaomi 24 Mi 1c | M6: 1-07 2 этаж
C7: На складе | H7: Стоит на складе | I7: Display | J7: Dell P2419H | M7: 1-07 2 этаж | N7: CN-0X046X
C8: Wen Jinqiu | I8: Display | J8: Lenovo C24-20 | N8: V5CGA557 | X8: Фоменков В.А. | Y8: Без акта 05.12.2025
B9: 1568 | C9: Земцова Анастасия | G9: Инженер-технолог (1 категории) MD, AS | I9: Display | J9: Lenovo 19" LT 1952p Black | L9: 00000000329 | N9: V9-VFRV1
A10: =#REF!+1 -> #REF! | B10: 11355 | C10: Комаров Дмитрий Александрович | D10: Модернизация не требуется/normal (no need to upgrade) | E10: Rus | F10: Komarov Dmitry | G10: Младший инженер по внедрению информационных систем 2 категории | H10: RDC, ISS, MSG | I10: AiO, mouse, keyboard | J10: AiO Acer Aspire C24-1800 | K10: MES | N10: 1-07 Второй этаж | O10: DQBKLCD001338014D13000 | P10: ="RUTL-" & RIGHT(O10,8) -> RUTL-14D13000 | Q10: Внесены в Passwork | R10: Libre office | V10: ULTRAVNC / MESH | W10: LOCAL ADMIN | X10: Мартынов Д. | Y10: Акт 06.03.2026
B11: 12657 | C11: Евсиков Константин | I11: SSD SATA 256 | J11: Patrior
D13: будет 970
C14: было 622 | D14: СУММА | E14: Итоговое по пк с 1 владельцем | F14: Итоговое по общим (92) | G14: Итоговое по техническим (52) | H14: Итоговое по складу | I14: Итоговое ЖМР(23) | J14: Итоговое RDD новое
D15: =SUM(E15:J15) -> 35 | E15: =COUNTA('ПК с 1 владельцем'!P:P)-1 -> 1 | F15: =COUNTA('ПК с 2 и более владельцами'!P:P)-1 -> 2 | G15: =COUNTA('Технические ПК'!P:P)-1 -> 2 | H15: =COUNTA('Склад, ремонт, ожидающие'!P:P)-1 -> 1 | I15: =COUNTA('ДонМотор(КАЛУГА)'!N:N)-1 -> 23 | J15: =COUNTA('ОПГ РНДМоушен'!O:O)-1 -> 6
C16: ИТОГО | D16: =(622+130+1+21+3+5+18+5+2+15+5+16+20+89)-10+(39+4+59+53+38)-9-14-2 -> 1110 | H16: 5- write off/ 8-неприкасаемый резерв/ 3-стоят в подразделениях / 14-ждут ремонт итого
B17: 20.11.2024 -645 | H17: =H15-(5+8+3+14) -> -29
B18: 21.11.2024 -646
B19: 22.11.2024 -649
B20: 25.11.2024 -654
B21: 25.11.2024 -655
B22: 26.11.2024 -655
B23: 27.11.2024 -655
B24: 28.11.2024 -656
B25: 29.11.2024 -671
B26: 03.12.2024 -678
B27: 03.12.2024 -679
B28: 06.12.2024 -683
B29: 09.12.2024-692
... B57: 15-09-2025-827 (792+15 это наши +18 ЖМР+)+2 на списание по браку
B58: 17-10-2025-843 (791+15+16 это наши +19 ЖМР)+2 на списание по браку | C58: =791+15+16+19+2 -> 843 | D58: =791+15+16+19+2 -> 843
B59: 13-11-2025 -834(822 это наши +19 ЖМР+)+2 на списание по браку погдготовлено/передано на утилизацию 9 ПК | C59: =843-9 -> 834
B60: 14-11-2025 -855(823+20(ср.закуп.) это наши +19 ЖМР+)+2 на списание по браку 09-12-2025 списано/передано на утилизацию 9 ПК | C60: =(823+19+2+20)-9 -> 855
B61: 28-11-2025 -896(823+20(ср.закуп.) это наши +23 ЖМР+)+2 на списание по браку+39 по тендеру RDD 09-12-2025 списано/передано на утилизацию 9 ПК | C61: =823+20+23+39-9 -> 896
B62: 09-12-2025 -887(823+20(ср.закуп.) это наши +23 ЖМР+)+2 на списание по браку+39 по тендеру RDD 09-12-2025 списано/передано на утилизацию 9 ПК 12-12-2025 списано/передано на утилизацию 9 ПК | C62: =823+20+23+39-18 -> 887
B63: 19-12-2025 -946(823+20(ср.закуп.) это наши +23 ЖМР+)+2 на списание по браку+39+59 по тендеру RDD 09-12-2025 списано/передано на утилизацию 9 ПК 12-12-2025 списано/передано на утилизацию 9 ПК | C63: =823+20+23+39+59-18 -> 946
B64: 19-12-2025 -932(823+20(ср.закуп.) это наши +23 ЖМР+)+2 на списание по браку+39+59 по тендеру RDD 09-12-2025 списано/передано на утилизацию 9 ПК 12-12-2025 списано/передано на утилизацию 9 ПК 24-12-2025 списано/передано на утилизацию 14 ПК | C64: =823+20+23+39+59-32 -> 932
B65: 20-01-2026 -930(823+20(ср.закуп.) это наши +23 ЖМР+)-2 на списание по браку( легализовали сторно эйсеров от 01-04-25)+39+59 по тендеру RDD 09-12-2025 списано/передано на утилизацию 9 ПК 12-12-2025 списано/передано на утилизацию 9 ПК 24-12-2025 списано/передано на утилизацию 14 ПК | C65: =(823+20+23+39+59)-(9+9+14+2) -> 930
B66: 27-03-2026 -1021(843++39+59 по тендеру RDD+53+38 по тендеру для новых цехов) это наши +23 ЖМР 2 на списание по браку( легализовали сторно эйсеров от 01-04-25) 09-12-2025 списано/передано на утилизацию 9 ПК 12-12-2025 списано/передано на утилизацию 9 ПК 24-12-2025 списано/передано на утилизацию 14 ПК | C66: =(823+20+23+39+59+53+38)-(9+9+14+2) -> 1021
B67: 06-04-2026 -1110(843++39+59 по тендеру RDD+53+38+89 по тендеру для новых цехов) это наши +23 ЖМР 2 на списание по браку( легализовали сторно эйсеров от 01-04-25) 09-12-2025 списано/передано на утилизацию 9 ПК 12-12-2025 списано/передано на утилизацию 9 ПК 24-12-2025 списано/передано на утилизацию 14 ПК | C67: =(823+20+23+39+59+53+38+89)-(9+9+14+2) -> 1110

Sheet Лист ожидания
C1: Дата поступления информации | D1: Дата выдачи ПК | E1: Источник информации о потребности в пк | J1: Дата выхода сотрудника /дата перевода сотрудника | K1: Приоритет выдачи (1 - высокий, 2 - средний, 3 - низкий) | L1: Тип потребности (новый/замена/перевод/промоушен/выход из декрета/временное совм. исп. с др.спец) | M1: Имя сотрудника | N1: ID | O1: Должность | P1: Подразделение | Q1: Руководитель | R1: Кто подал запрос? | S1: Тип ПК | T1: Какой решено (SN или чей)
E2: Потребность? (подписанный документ) | F2: Служебная записка на сотрудника? | G2: Запрос в ITSM? | H2: Уведомление. от HR | I2: Другое
A3: 1 | B3: =#REF!+1 -> #REF! | C3: 46054 | D3: Техника RDD | E3: 1 | H3: 1 | I3: потребность с запозданием 04-02-2026 | J3: 2026 | L3: Новый_2026 | M3: Железцов Артем | O3: Инженер технолог | P3: ES_QT | Q3: - | R3: - | S3: L1

Sheet Проекторы
A1: ПРОЕКТОРЫ
A2: ИНВ № | B2: s/n | C2: model | D2: location
A3: 100000003399 | B3: MRJU711001311004B05900 | C3: Проектор Acer X1528i HDMI,Wifi | D3: 2 этаж переговорка с поликомом | E3: 1-09
A4: на учет | B4: MRJV811001432008D58410 | C4: Проектор Acer X1529HK | D4: переговорная 1-07-2.1(большая переговорка GD ) | E4: 1-07
A5: на учет | B5: PD49R01199000 | C5: Проектор BenQ MH550 | D5: 1-07-2.2 Переговорка | E5: 1-07
A6: 100000001583 | C6: Проектор BenQ MW550 | D6: Переговорная 4 этаж RD | E6: 1-07
A7: 100000004256 | B7: PDZAP01329000 | C7: Проектор BenQ MW550 | D7: У Антона узнать серийный номер | E7: 1-09 2 этаж
A8: 100000005482 | B8: PD49R01198000 | C8: Проектор BenQ MW550 | D8: 1-09 3 этаж переговорная | E8: 1-09 3-й этаж | F8: Отдаём в 1-09 3 этаж
A9: Z000058/140000182 | C9: Проектор Epson EB-980 W/2 | D9: Переговорная 3 Уч класс | E9: 1-07
A10: Z000131/140000035 | C10: Проектор Epson EB-965H | D10: Переговорная 3 эт FD | E10: 1-07
A11: 140000177 | C11: Проектор Epson EH-TW610/1 | D11: Hr общий | E11: 1-07
A12: 21040(1) | C12: Проектор Epson EB-E001 | D12: Переговорная 1 этаж | E12: 1-07
A13: 21040(2) | B13: X7E69700849 | C13: Проектор Epson EB-E001 | D13: класс hse | E13: 1-07
A14: Цеха
A15: 140000179 | C15: Проектор Epson EH-TW610/3 | D15: SW Уч класс | E15: 01-02
A16: Z000034/140000181 | C16: Проектор Epson EB-980 W/1 | D16: ASSE Уч класс | E16: 01-04
A17: 1000000001621 | B17: 1-02 mu sw | C17: Проектор BenQ MW550 | D17: UTL Уч класс | E17: 1-13
A18: 1000000001622 | C18: Проектор BenQ MW550 | D18: QI Уч класс | E18: 01-04
A19: 140000178 | C19: Проектор Epson EH-TW610/2 | D19: PAINT Уч класс | E19: 01-03
A20: 140000211 | C20: Проектор Epson EB-970/1 | D20: 1-06 переговорная 2 этаж | E20: 01-06
A21: Z000033/140000183 | B21: x4zg8400031 | C21: Проектор Epson EB-980 W/3 | D21: Комната рядом с переговорной | E21: 1-03
A22: Z000013/140000049 | B22: VSBK6500207 | C22: Проектор Epson EB-965H | D22: Цех двигателей в комнате обучения с Polycom (новый офис, который не офис, а склад раздевалка | E22: 1-46 (Цех Двигаталей)
A23: на складе
A24: 100000003398 | B24: MRJU7110013110047A5900(13110047A5900) | C24: Проектор Acer X1528i HDMI,Wifi | D24: 2 этаж переговорная с поликомом | E24: 1-07 | F24: он на ремонте/списание через PD по корректировочной накладной
A25: 10000001726 | B25: СЛОМАН | C25: Проектор Epson EH-TW610 | D25: лежит на складе | E25: 1-07 | F25: Нужны линзы/подготовим доки на списание
A26: на учет | C26: Проектор BenQ MH550 | D26: купили для QA | E26: 1-07

Sheet ФотоВидео
A1: ФОТО/Видео
A2: ИНВ № | B2: s/n | C2: model | D2: location
E3: 1-07 3 этаж
E4: 1-09 1 этаж
A5: на складе
E6: 1-07 2 этаж
E7: 1-07 2 этаж
E8: 1-07 2 этаж

Sheet RD_Motion(ownPC)
A1: № | B1: Табельный номер / Employee ID | C1: Физлицо / Owner | D1: История модернизаций, ремонтов / Modernisation, repairing history | E1: Тип домена / Domain Type | F1: Имя на английском / English name | G1: Должность / Position (Rus / Eng) | H1: Отдел / Department | I1: Комплектация / Equipment | J1: Тип и модель ПК / PC type and model | K1: Инвентарный номер / Inventory number | L1: Серийный номер / Serial Number | M1: Имя компьютера / PC Domain Name | N1: Тип ПО офис / Office type | O1: Ключ офиса / License key Office | P1: ОС тип / OS Type | Q1: Ключ ОС / Key OS | R1: ПО удалённого управления / Remote control | S1: Админ права / Admin permissions | T1: Дата выдачи / Issue Date | U1: Дата покупки / Purchasing Date | V1: Примечание / Comment
A2: 1 | B2: выдан но не настроен | C2: Ягелова Татьяна Владимировна | D2: новый | E2: no domain | F2: Yagelova Tatiana | G2: Заместитель директора | H2: R&D | I2: Laptop | J2: MSI Modern 15 F1MG-800XRU | K2: - | L2: C2509N0008428 | M2: no domain | N2: Professional Plus 2019 / Активирован | P2: Windows 11 | S2: не настроен | T2: 45996 | U2: 45996
A3: 2 | B3: выдан но не настроен | C3: Ягелова Татьяна Владимировна | D3: новый | E3: no domain | F3: Yagelova Tatiana | G3: Заместитель директора | H3: R&D | I3: Laptop | J3: MSI Modern 15 F1MG-800XRU | K3: - | L3: C2509N0008430 | M3: no domain | N3: Professional Plus 2019 / Активирован | P3: Windows 11 | S3: не настроен | T3: 45996 | U3: 45996
